Workbook
Name _c検索基準日: #REF!
Name _集計月: #REF!
Name スライサー_加工内容: #N/A
Name スライサー_加工内容1: #N/A
Name スライサー_年月__月: #N/A
Name スライサー_年月__月1: #N/A
Name スライサー_年月__月2: #N/A
Name スライサー_年月__月3: #N/A
Name スライサー_年月__月31: #N/A
Name スライサー_年月__年: #N/A
Name スライサー_年月__年1: #N/A
Name スライサー_年月__年2: #N/A
Name スライサー_年月__年3: #N/A
Name スライサー_年月__年31: #N/A
Name 再入力対象依頼No: #REF!
Name 製品参照ｺｰﾄﾞ: #REF!
Name 品種マスタリスト: INDEX(#REF!,0)
Name 品種マスタリスト: INDEX(#REF!,0)

Sheet _t受注ﾌｧｲﾙ
A1: 受注ﾌｧｲﾙ | B1: 依頼Ｎｏ | C1: 入力区分 | D1: 加工区分 | E1: 入力担当 | F1: 入力日 | G1: 受付Ｎｏ | H1: 品名 | I1: 製品 | J1: 梱-等1 | K1: 色1 | L1: 区分1 | M1: 枝番 | N1: 数量1 | O1: ＥＣ面 | P1: ﾄﾘﾐﾝｸﾞ | Q1: 割数 | R1: 品名1 | S1: 原反 | T1: 梱-等 | U1: 色 | V1: 区分 | W1: 数量 | X1: 在庫場所 | Y1: 投入場所 | Z1: 投入日 | AA1: 加工内容 | AB1: 特記事項1 | AC1: 特記事項2 | AD1: 特記事項3 | AE1: 用途 | AF1: ユーザー | AG1: 希望納期 | AH1: 調整納期 | AI1: 加工賃 | AJ1: 契約Ｎｏ | AK1: 原反ロール数 | AL1: 月数 | AM1: 受注金額 | AN1: 受注数 | AO1: 単価 | AP1: 受注金額(修正) | AQ1: masterBase商品(製品) | AR1: masterBase商品(原反) | AS1: 加工完了日 | AT1: 出来高１ | AU1: 出来高 | AV1: 加工金額 | AW1: 列4 | AX1: 桁製品 | AY1: 桁梱-等 | AZ1: 桁色 | BA1: 桁区分 | BB1: 桁枝番 | BC1: 桁原反 | BD1: 桁梱-等5 | BE1: 桁色6 | BF1: 桁区分7 | BG1: 列8 | BH1: 月 | BI1: 単価9 | BJ1: 金額 | BK1: ｴﾗｰ：単価1 | BL1: ｴﾗｰ数量1 | BM1: ｴﾗｰ：単価2 | BN1: ｴﾗｰ数量2 | BO1: ｴﾗｰ：単価3 | BP1: ｴﾗｰ数量3 | BQ1: ｴﾗｰ：単価4 | BR1: ｴﾗｰ数量4 | BS1: ｴﾗｰ：単価5 | BT1: ｴﾗｰ数量5 | BU1: 合計金額 | BV1: Column74 | BW1: Column75 | BX1: Column76 | BY1: Column77 | BZ1: Column78 | CA1: Column79 | CB1: Column80 | CC1: Column81 | CD1: Column82 | CE1: Column83 | CF1: 受注ﾌｧｲﾙ_1 | CG1: Sheet | CH1: false
A2: 受注ﾌｧｲﾙ | B2: W7-4 | C2: 通常入力 | D2: 後加工 | E2: 古家 | F2: 46219 | H2: 6783 | I2: 15020-JX5R-1300X300 | J2: F-A | K2: ナチュラル | L2: R | N2: 1200 | O2: Ｈ面 | Q2: 1 | R2: 6780 | S2: 15020-AX5R-1300X300 | T2: F-A | U2: ナチュラル | V2: P | W2: 2,700 | X2: 滋賀 | Y2: EC | Z2: 46213 | AA2: EC,検査 | AB2: ＊欠点個数確認チェック ラベル◎ 確認済み明記 | AE2: W（自動車） | AF2: 共和天１ | AG2: 46218 | AH2: 46225 | AI2: 38 | AJ2: 186811R | AK2: 9 | AL2: 7 | AN2: 1200 | AO2: 38 | AP2: 45600 | AQ2: A2F20JXD0300FN1 | AR2: B2F20AXD0300FN1 | CF2: 受注ﾌｧｲﾙ | CG2: Sheet | CH2: FALSE
A3: 受注ﾌｧｲﾙ | B3: W7-5 | C3: 通常入力 | D3: 後加工 | E3: 砂田 | F3: 46218 | H3: 6783 | I3: 15020-JX5R-1440X300 | J3: F-A | K3: ナチュラル | L3: R | N3: 3300 | O3: Ｈ面 | Q3: 1 | R3: 6780 | S3: 15020-AX5R-1440X300 | T3: F-A | U3: ナチュラル | V3: P | W3: 3900 | X3: 滋賀 | Y3: EC | Z3: 46213 | AA3: EC,検査 | AB3: ＊欠点個数確認チェック ラベル◎ 確認済み明記 | AE3: W（自動車） | AF3: 共和天１ | AG3: 46220 | AH3: 46221 | AI3: 38 | AJ3: 186812L | AK3: 13 | AL3: 7 | AN3: 3300 | AO3: 38 | AP3: 125400 | AQ3: A2F20JXE4300FN1 | AR3: B2F20AXE4300FN1 | CF3: 受注ﾌｧｲﾙ | CG3: Sheet | CH3: FALSE
A4: 受注ﾌｧｲﾙ | B4: JR260701 | C4: 通常入力 | D4: TPI | E4: 砂田 | F4: 46195 | H4: D33 | I4: 30020-A05W-870X97 | J4: F-A | K4: LG | N4: 1940 | P4: 有 | Q4: 1 | R4: 7A1 | S4: FEL3002BY05-10WD-1000X100 | U4: LG | W4: 1400 600 | X4: 湖南 | Y4: SEC | AA4: SEC,ｽﾘｯﾄ | AB4: 投入ﾛｯﾄ：26060001，0041，0042，0050,0064,0075 | AE4: JR（屋根） | AF4: 自動転記 | AG4: 46211 | AH4: 46211 | AI4: 43 | AJ4: P75564 | AK4: 20 | AL4: 7 | AN4: 1940 | AO4: 43 | AP4: 83420 | AQ4: A3O20A087097FL1 | AR4: B3O202BA0100FLA B3O202BA0100FLA | CF4: 受注ﾌｧｲﾙ | CG4: Sheet | CH4: FALSE
A5: 受注ﾌｧｲﾙ | B5: Y7-1 | C5: 通常入力 | D5: 後加工 | E5: 古家 | F5: 46217 | H5: 6713 | I5: 30020-BY00-640X250 | J5: F-A | L5: C | N5: 6000 | Q5: 1 | R5: 6710 | S5: 30040-AY00-640X250 | T5: F-A | V5: C | W5: 3,000 | Z5: 46204 | AA5: ｽﾗｲｽ | AE5: Y（工材） | AF5: フカサワ | AG5: 46209 | AH5: 46212 | AI5: 11 | AJ5: 187073A | AK5: 12 | AL5: 7 | AN5: 6000 | AO5: 11 | AP5: 66000 | AQ5: A2O20BY64250FN1 | AR5: B2O40AY64250FN1 | CF5: 受注ﾌｧｲﾙ | CG5: Sheet | CH5: FALSE
A6: 受注ﾌｧｲﾙ | B6: Y7-2 | C6: 通常入力 | D6: 後加工 | E6: 古家 | F6: 46217 | H6: 6713 | I6: 30020-8G00-250X200 | J6: J-A | L6: C | N6: 1600 | P6: 有 | Q6: 1 | R6: 6710 | S6: 30040-AG00-1000X200 | T6: F-A | V6: C | W6: 200 | X6: 滋賀 | Y6: SEC | Z6: 46205 | AA6: SEC,ｽﾘｯﾄ | AE6: Y（工材） | AF6: ゼネラル化成 | AG6: 46210 | AH6: 46211 | AI6: 10 | AJ6: 187074V | AK6: 1 | AL6: 7 | AN6: 1600 | AO6: 10 | AP6: 16000 | AQ6: A2O208G25200JN1 | AR6: B2O40AGA0200FN1 | CF6: 受注ﾌｧｲﾙ | CG6: Sheet | CH6: FALSE
A7: 受注ﾌｧｲﾙ | B7: Y7-3 | C7: 通常入力 | D7: 後加工 | E7: 古家 | F7: 46217 | H7: 6713 | I7: 30020-8G00-310X200 | J7: H-A | L7: C | N7: 1200 | P7: 有 | Q7: 1 | R7: 6710 | S7: 30040-AG00-1000X200 | T7: F-A | V7: C | W7: 200 | X7: 滋賀 | Y7: SEC | Z7: 46205 | AA7: SEC,ｽﾘｯﾄ | AE7: Y（工材） | AF7: ゼネラル化成 | AG7: 46210 | AH7: 46211 | AI7: 10 | AJ7: 187075B | AK7: 1 | AL7: 7 | AN7: 1200 | AO7: 10 | AP7: 12000 | AQ7: A2O208G25200HN1 | AR7: B2O40AGA0200FN1 | CF7: 受注ﾌｧｲﾙ | CG7: Sheet | CH7: FALSE
A8: 受注ﾌｧｲﾙ | B8: V6-16 | C8: 通常入力 | D8: 後加工 | E8: 砂田 | F8: 46192 | H8: 6713 | I8: 50090-AY0B-900X100 | J8: F-A | K8: BK0 | L8: C | N8: 100 | Q8: 1 | R8: 6713 | S8: 50090-AY0B-900X100 | T8: F-A | U8: BK0 | V8: C | W8: 100 | X8: 湖南 | Y8: ｽﾗｲｽ | AA8: ｽﾗｲｽ，巻き返し | AB8: スキン取り | AC8: ロット5CNC261 | AE8: V（TPI） | AF8: ＴＰＩ湖南 | AG8: 46192 | AH8: 46192 | AI8: 35 | AJ8: 186455R | AK8: 1 | AL8: 6 | AN8: 100 | AO8: 35 | AP8: 3500 | AQ8: A2Q60AY90100FB4 | AR8: B2Q60AY90100FN1 | CF8: 受注ﾌｧｲﾙ | CG8: Sheet | CH8: FALSE
A9: 受注ﾌｧｲﾙ | B9: W7-1 | C9: 通常入力 | D9: 後加工 | E9: 砂田 | F9: 46192 | H9: 6783 | I9: 15020-JX5R-1440X300 | J9: F-A | L9: R | N9: 6000 | O9: Ｈ面 | Q9: 1 | R9: 6780 | S9: 15020-AX5R-1440X300 | T9: F-A | V9: P | W9: 6,000 | X9: 滋賀 | Y9: EC | Z9: 46206 | AA9: EC,ゴミ除去 | AB9: ＊欠点個数確認チェック ラベル◎ 確認済み明記 | AE9: W（自動車） | AF9: 共和天１ | AG9: 46212 | AH9: 46212 | AI9: 38 | AJ9: 186643J | AK9: 20 | AL9: 7 | AN9: 6000 | AO9: 38 | AP9: 228000 | AQ9: A2F20JXE4300FN1 | AR9: B2F20AXE4300FN1 | CF9: 受注ﾌｧｲﾙ | CG9: Sheet | CH9: FALSE
A10: 受注ﾌｧｲﾙ | B10: W7-2 | C10: 通常入力 | D10: 後加工 | E10: 細川 | F10: 46212 | H10: 6783 | I10: 15020-JX5R-1300X300 | J10: F-A | L10: R | N10: 6000 | O10: Ｈ面 | Q10: 1 | R10: 6780 | S10: 15020-AX5R-1300X300 | T10: F-A | V10: P | W10: 6,000 | X10: 滋賀 | Y10: EC | Z10: 46206 | AA10: EC,ゴミ除去 | AB10: ＊欠点個数確認チェック ラベル◎ 確認済み明記 | AE10: W（自動車） | AF10: 共和天１ | AG10: 46216 | AH10: 46216 | AI10: 38 | AJ10: 186642P | AK10: 20 | AL10: 7 | AN10: 6000 | AO10: 38 | AP10: 228000 | AQ10: A2F20JXD0300FN1 | AR10: B2F20AXD0300FN1 | CF10: 受注ﾌｧｲﾙ | CG10: Sheet | CH10: FALSE
A11: 受注ﾌｧｲﾙ | B11: W7-3 | C11: 通常入力 | D11: 後加工 | E11: 砂田 | F11: 46192 | H11: 6783 | I11: 15020-JX5R-1440X300 | J11: F-A | L11: R | N11: 5400 | O11: Ｈ面 | Q11: 1 | R11: 6780 | S11: 15020-AX5R-1440X300 | T11: F-A | V11: P | W11: 6,000 | X11: 滋賀 | Y11: EC | Z11: 46209 | AA11: EC,ゴミ除去 | AB11: ＊欠点個数確認チェック ラベル◎ 確認済み明記 | AE11: W（自動車） | AF11: 共和天１ | AG11: 46217 | AH11: 46217 | AI11: 38 | AJ11: 186644A | AK11: 20 | AL11: 7 | AN11: 5400 | AO11: 38 | AP11: 205200 | AQ11: A2F20JXE4300FN1 | AR11: B2F20AXE0300FN1 | CF11: 受注ﾌｧｲﾙ | CG11: Sheet | CH11: FALSE
A12: 受注ﾌｧｲﾙ | B12: Y6-18 | C12: 通常入力 | D12: 後加工 | E12: 古家 | F12: 46191 | G12: Y6-18 | H12: 6713 | I12: 30022-BG00-1000X200 | J12: F-A | K12: WH1 | L12: C | N12: 12000 | Q12: 1 | R12: 6710 | S12: 30044-AG00-1000X200 | T12: F-A | U12: WH1 | V12: C | W12: 6,000 | X12: 滋賀 | Y12: ｽﾗｲｽ | Z12: 46196 | AA12: ｽﾗｲｽ | AC12: 検査前入庫依頼 | AE12: Y（工材） | AF12: 大伸工業 | AG12: 46198 | AH12: 46198 | AI12: 1 | AJ12: 185153B | AK12: 30 | AL12: 6 | AN12: 12000 | AO12: 1 | AP12: 12000 | AQ12: A2O22BGA0200FW3 | AR12: B2O44AGA0200FBP | CF12: 受注ﾌｧｲﾙ | CG12: Sheet | CH12: FALSE
A13: 受注ﾌｧｲﾙ | B13: Y6-19 | C13: 通常入力 | D13: 後加工 | E13: 古家 | F13: 46191 | G13: Y6-19 | H13: 6713 | I13: 30033-BY00-640X200 | J13: F-A | K13: GA0 | L13: C | N13: 20000 | Q13: 1 | R13: 6710 | S13: 30066-AY00-640X200 | T13: F-A | U13: GA0 | V13: C | W13: 10,000 | X13: 滋賀 | Y13: ｽﾗｲｽ | Z13: 46195 | AA13: ｽﾗｲｽ | AC13: 検査前入庫依頼 | AE13: Y（工材） | AF13: 阿部加工 | AG13: 46202 | AH13: 46202 | AI13: 11 | AJ13: 185154K | AK13: 50 | AL13: 6 | AN13: 20000 | AO13: 11 | AP13: 220000 | AQ13: A2O33BY64200FG3 | AR13: B2O66AY64200FG3 | CF13: 受注ﾌｧｲﾙ | CG13: Sheet | CH13: FALSE
A14: 受注ﾌｧｲﾙ | B14: W6-21 | C14: 通常入力 | D14: 後加工 | E14: 古家 | F14: 46191 | H14: 6783 | I14: 15020-JX5R-1440X300 | J14: F-A | L14: R | N14: 6000 | O14: Ｈ面 | Q14: 1 | R14: 6780 | S14: 15020-AX5R-1440X300 | T14: F-A | V14: P | W14: 6,000 | X14: 滋賀 | Y14: EC | Z14: 46192 | AA14: EC,検査 | AB14: ＊欠点個数確認チェック ラベル◎ 確認済み明記 | AE14: W（自動車） | AF14: 共和天１ | AG14: 46202 | AH14: 46202 | AI14: 38 | AJ14: 186336S | AK14: 20 | AL14: 6 | AN14: 6000 | AO14: 38 | AP14: 228000 | AQ14: A2F20JXE4300FN1 | AR14: B2F20AXE4300FN1 | CF14: 受注ﾌｧｲﾙ | CG14: Sheet | CH14: FALSE
A15: 受注ﾌｧｲﾙ | B15: W6-22 | C15: 通常入力 | D15: 後加工 | E15: 古家 | F15: 46191 | H15: 6783 | I15: 15020-JX5R-1300X300 | J15: F-A | L15: R | N15: 6000 | Q15: 1 | R15: 6780 | S15: 15020-AX5R-1300X300 | T15: F-A | V15: P | W15: 6,000 | X15: 滋賀 | Y15: EC | Z15: 46195 | AA15: EC,検査 | AB15: ＊欠点個数確認チェック ラベル◎ 確認済み明記 | AE15: W（自動車） | AF15: 共和天１ | AG15: 46203 | AH15: 46203 | AI15: 38 | AJ15: 186526W | AK15: 20 | AL15: 6 | AN15: 6000 | AO15: 38 | AP15: 228000 | AQ15: A2F20JXD0300FN1 | AR15: B2F20AXD0300FN1 | CF15: 受注ﾌｧｲﾙ | CG15: Sheet | CH15: FALSE
A16: 受注ﾌｧｲﾙ | B16: W6-23 | C16: 通常入力 | D16: 後加工 | E16: 古家 | F16: 46191 | H16: 6783 | I16: 20020-AP17-1120X300 20020-AP17-1120X297 20020-AP17-1120X289 | J16: F-A | L16: P | N16: 2400 297 289 | Q16: 1 | R16: 6780 | S16: 20020-AP17-1220X300 | T16: F-A | V16: P | W16: 3,000 | Z16: 46192 | AA16: ｽﾘｯﾄ | AB16: ＊欠点個数確認チェック ラベル◎ | AE16: W（自動車） | AF16: 共和新城 | AG16: 46197 | AH16: 46197 | AI16: 17 | AJ16: 186334G 186527R 186528L | AK16: 10 | AL16: 6 | AN16: 2400 297 289 | AO16: 17 | AP16: 50762 | AQ16: A2K20APB5300FN1 | AR16: B2K20APC2300FN1 | CF16: 受注ﾌｧｲﾙ | CG16: Sheet | CH16: FALSE
A17: 受注ﾌｧｲﾙ | B17: C6-9 | C17: 通常入力 | D17: 後加工 | E17: 古家 | F17: 46191 | H17: 6713 | I17: 30020-KG00-935X200 | J17: F-A | K17: GA1 | L17: V | N17: 400 | Q17: 1 | R17: 6710 | S17: 30040-AG00-935X200 | T17: F-A | U17: GA1 | V17: C | W17: 200 | X17: 滋賀 | Y17: SEC | Z17: 46195 | AA17: SEC,巻き返し | AB17: 穴無し 3インチ紙管 | AE17: Y（工材） | AF17: 東邦紙工 | AG17: 46198 | AH17: 46198 | AI17: 26 | AJ17: 186371M | AK17: 1 | AL17: 6 | AN17: 400 | AO17: 26 | AP17: 10400 | AQ17: A2O20KG93200FG4 | AR17: B2O40AG93200FG4 | CF17: 受注ﾌｧｲﾙ | CG17: Sheet | CH17: FALSE
A18: 受注ﾌｧｲﾙ | B18: C6-10 | C18: 通常入力 | D18: 後加工 | E18: 砂田 | F18: 46197 | H18: 6713 6713 | I18: 0R040-8Y0B-870X200 0R040-8Y0B-870X200 | J18: F-A F-A | K18: GA1 GA1 | L18: H Q | N18: 1600 1600 | Q18: 1 | R18: 6710 | S18: 50080-AY0B-870X200 | T18: F-A | U18: GA1 | V18: C | W18: 1600 | X18: 湖南 | Y18: SEC | Z18: 46204 | AA18: ＳＥＣ | AE18: Y（工材） | AF18: 屋根 | AG18: 46206 | AH18: 46206 | AI18: 13 | AK18: 9 | AL18: 7 | AN18: 1600 1600 | AO18: 13 | AP18: 41600 | AQ18: A2P408Y87200FG4 A2P408Y87200FGD | AR18: B2Q60AY87200FG4 | CF18: 受注ﾌｧｲﾙ | CG18: Sheet | CH18: FALSE
A19: 受注ﾌｧｲﾙ | B19: C6-11 | C19: 通常入力 | D19: 後加工 | E19: 砂田 | F19: 46202 | H19: 6713 | I19: 0R040-8Y0B-680X200 | J19: F-A | K19: BG1 | L19: C | N19: 18800 | Q19: 1 | R19: 6710 | S19: 50080-AY0B-680X200 | T19: F-A | U19: BG1 | V19: C | W19: 9400 | X19: 滋賀 | Y19: SEC | Z19: 46204 | AA19: SEC | AE19: Y（工材） | AF19: 屋根 | AG19: 46209 | AH19: 46209 | AI19: 13 | AJ19: 186932F | AK19: 48 | AL19: 7 | AN19: 18800 | AO19: 13 | AP19: 244400 | AQ19: A2P408Y68200FB1 | AR19: B2Q60AY68200FB1 | CF19: 受注ﾌｧｲﾙ | CG19: Sheet | CH19: FALSE
A20: 受注ﾌｧｲﾙ | B20: C6-12 | C20: 通常入力 | D20: 後加工 | E20: 砂田 | F20: 46198 | H20: 6713 | I20: 0R040-8Y0B-870X200 | J20: F-A | L20: C | N20: 24000 | Q20: 1 | R20: 6710 | S20: 50080-AY0B-870X200 | T20: F-A | V20: C | W20: 12,000 | X20: 滋賀 | Y20: SEC | Z20: 46205 | AA20: SEC | AE20: Y（工材） | AF20: 屋根 | AG20: 46180 | AH20: 46180 | AI20: 13 | AJ20: 186933W | AK20: 60 | AL20: 6 | AN20: 24000 | AO20: 13 | AP20: 312000 | AQ20: A2P408Y87200FN1 | AR20: B2Q60AY87200FN1 | CF20: 受注ﾌｧｲﾙ | CG20: Sheet | CH20: FALSE
A21: 受注ﾌｧｲﾙ | B21: JR260605 | C21: 通常入力 | D21: TPI | E21: 古家 | F21: 46191 | H21: 0 | I21: 40040-E10W-870X95 | N21: 190 | Q21: 1 | R21: 7A1 | S21: FEL4004AY-10WD-1000X100 | W21: 200 | X21: 湖南 | Y21: SEC | Z21: 46195 | AA21: SEC,ｽﾘｯﾄ | AB21: ４倍穴あけ | AE21: JR（屋根） | AG21: 46199 | AH21: 46199 | AI21: 43 | AJ21: P75558 | AK21: 2 | AL21: 6 | AN21: 190 | AO21: 43 | AP21: 8170 | AQ21: A3P40E187095FA1 | AR21: B3P404AA0100FA1 | CF21: 受注ﾌｧｲﾙ | CG21: Sheet | CH21: FALSE
A22: 受注ﾌｧｲﾙ | B22: GB60603 | C22: 通常入力 | D22: TPI | E22: 古家 | F22: 46191 | I22: 15030-JW07-760X3 | N22: 3 | Q22: 1 | S22: 15030-AW07- 760X 3 | W22: 3 | X22: 湖南 | Y22: ＥＣ | Z22: 46196 | AA22: EC | AE22: 小口加工 | AG22: 46196 | AH22: 46196 | AI22: 9 | AK22: 1 | AL22: 6 | AN22: 3 | AO22: 9 | AP22: 27 | AQ22: A3F30JW76050FN1 | AR22: B3F30AW76050FN1 | CF22: 受注ﾌｧｲﾙ | CG22: Sheet | CH22: FALSE
A23: 受注ﾌｧｲﾙ | B23: C6-6 | C23: 通常入力 | D23: 後加工 | E23: 砂田 | F23: 46199 | H23: 6713 6713 | I23: 0R040-8Y0B-680X200 0R040-8Y0B-680X197 | J23: F-A F-A | K23: GA1 GA1 | L23: C C | N23: 19600 394 | Q23: 1 | R23: 6710 | S23: 50080-AY0B-680X200 | T23: F-A | U23: GA1 | V23: C | W23: 10,000 | X23: 滋賀 | Y23: SEC | Z23: 46197 | AA23: SEC | AE23: Y（工材） | AF23: 屋根 | AG23: 46202 | AH23: 46202 | AI23: 13 | AJ23: 186046F 187062R | AK23: 50 | AL23: 6 | AN23: 19600 394 | AO23: 13 | AP23: 259922 | AQ23: A2P408Y68200FG1 A2P408Y68200FG1 | AR23: B2Q60AY68200FG4 | CF23: 受注ﾌｧｲﾙ | CG23: Sheet | CH23: FALSE
A24: 受注ﾌｧｲﾙ | B24: C6-7 | C24: 通常入力 | D24: 後加工 | E24: 砂田 | F24: 46190 | H24: 6713 6713 | I24: 0R040-8Y0B-870X200 0R040-8Y0B-870X200 0R040-8Y0B-870X196 0R040-8Y0B-870X196 | J24: F-A F-A | K24: GA1 GA1 | L24: H Q | N24: 9800 9800 196 196 | Q24: 1 | R24: 6710 | S24: 50080-AY0B-870X200 | T24: F-A | U24: GA1 | V24: C | W24: 10,000 | X24: 滋賀 | Y24: SEC | Z24: 46198 | AA24: SEC | AE24: Y（工材） | AF24: 屋根 | AG24: 46203 | AH24: 46203 | AI24: 13 | AJ24: 186047W 186048R 187435R 187436L | AK24: 50 | AL24: 6 | AN24: 9800 9800 196 196 | AO24: 13 | AP24: 259896 | AQ24: A2P408Y25200GN4 A2P408Y25200GND | AR24: B2Q60AY87200FG4 | CF24: 受注ﾌｧｲﾙ | CG24: Sheet | CH24: FALSE
A25: 受注ﾌｧｲﾙ | B25: C6-8 | C25: 通常入力 | D25: 後加工 | E25: 砂田 | F25: 46190 | H25: 6713 | I25: 0R040-8Y0B-520X200 0R040-8Y0B-520X197 0R040-8Y0B-520X198 0R040-8Y0B-520X199 | J25: F-A | K25: GA1 | L25: C | N25: 1400 197 198 199 | Q25: 1 | R25: 6713 | S25: 0R04-8Y0B-680X200 | T25: F-A | U25: GA1 | V25: C | W25: 2,000 | X25: 湖南 | Y25: ｽﾘｯﾄ | Z25: 46184 | AA25: ｽﾘｯﾄ | AE25: Y（工材） | AF25: 屋根 | AG25: 46188 | AH25: 46188 | AI25: 17 | AJ25: 185767T 185861B 185862K 186037H | AK25: 10 | AL25: 6 | AN25: 1400 197 198 199 | AO25: 17 | AP25: 33898 | AQ25: A2P408Y52200FG1 A2P408Y52200FG1 | AR25: B2P408Y68200FG4 | CF25: 受注ﾌｧｲﾙ | CG25: Sheet | CH25: FALSE
A26: 受注ﾌｧｲﾙ | B26: W6-18 | C26: 通常入力 | D26: 後加工 | E26: 砂田 | F26: 46190 | H26: 6783 6783 | I26: 20020-AP17-1450X60 20020-AP17-1550X240 | J26: F-A F-A | L26: P P | N26: 60 240 | P26: 有 | Q26: 1 | R26: 6780 | S26: 20020-AP17-1550X300 | T26: F-A | V26: P | W26: 500 | X26: 湖南 | Y26: ｽﾘｯﾄ | Z26: 46188 | AA26: スリット、分割 | AE26: W（自動車） | AF26: 共和新城 | AG26: 46190 | AH26: 46190 | AI26: 32 | AJ26: 185860V 186182A | AK26: 1 | AL26: 6 | AN26: 60 240 | AO26: 32 | AP26: 9600 | CF26: 受注ﾌｧｲﾙ | CG26: Sheet | CH26: FALSE
A27: 受注ﾌｧｲﾙ | B27: E6-5 | C27: 通常入力 | D27: 後加工 | E27: 砂田 | F27: 46190 | H27: 6783 | I27: 18030-JX5R-1390X250 | J27: F-A | L27: B | N27: 3250 | O27: Ｈ面 | Q27: 1 | R27: 6780 | S27: 18030-AX5R-1390X250 | T27: F-A | V27: B | W27: 3250 | X27: 滋賀 | Y27: EC | Z27: 46191 | AA27: EC,巻き返し | AB27: Ｑ面外巻き（ｲﾝﾗｲﾝEC仕様） | AE27: B（輸出） | AF27: 共和興 | AG27: 46202 | AH27: 46202 | AI27: 31 | AJ27: 186188R | AK27: 13 | AL27: 6 | AN27: 3250 | AO27: 31 | AP27: 100750 | AQ27: A2I30JXD9250FN1 | AR27: B2I30AXD9300FN1 | CF27: 受注ﾌｧｲﾙ | CG27: Sheet | CH27: FALSE
A28: 受注ﾌｧｲﾙ | B28: Y6-29 | C28: 通常入力 | D28: 後加工 | E28: 砂田 | F28: 46190 | H28: 6713 | I28: 10010-FY00-740X200 | J28: F-A | K28: GR0 | L28: C | N28: 200 | Q28: 1 | R28: 6710 | S28: 10010-AY00-750X200 | T28: F-A | U28: GR0 | V28: C | W28: 200 | X28: 湖南 | Y28: ｴﾝﾎﾞｽ | Z28: 46190 | AA28: ｴﾝﾎﾞｽ | AB28: コクヨシボ | AE28: Y（工材） | AF28: ニックス | AG28: 46191 | AH28: 46191 | AI28: 1 | AJ28: 186245G | AK28: 1 | AL28: 6 | AN28: 200 | AO28: 1 | AP28: 200 | AQ28: A2A10FY74200FGF | AR28: B2A10AY75200FG6 | CF28: 受注ﾌｧｲﾙ | CG28: Sheet | CH28: FALSE
A29: 受注ﾌｧｲﾙ | B29: W6-19 | C29: 通常入力 | D29: 後加工 | E29: 砂田 | F29: 46190 | H29: 6783 | I29: 15020-JX5R-1300X300 | J29: F-A | L29: R | N29: 2400 | P29: 有 | Q29: 1 | R29: 6780 | S29: 15020-AX5R-1440X300 | T29: F-A | V29: P | W29: 2,400 | X29: 滋賀 | Y29: ｽﾘｯﾄ | Z29: 46191 | AA29: ｽﾘｯﾄ，EC，検査 | AB29: ＊欠点個数確認チェック ラベル◎ 確認済み明記 | AE29: W（自動車） | AF29: 共和天１ | AG29: 46196 | AH29: 46196 | AI29: 55 | AJ29: 186178Z | AK29: 8 | AL29: 6 | AN29: 2400 | AO29: 55 | AP29: 132000 | AQ29: A2F20JXD0300FN1 | AR29: B2F20AXE4300FN1 | CF29: 受注ﾌｧｲﾙ | CG29: Sheet | CH29: FALSE
A30: 受注ﾌｧｲﾙ | B30: W6-20 | C30: 通常入力 | D30: 後加工 | E30: 砂田 | F30: 46190 | H30: 6783 | I30: 15020-JX5R-1440X300 | J30: F-A | L30: R | N30: 6600 | O30: Ｈ面 | Q30: 1 | R30: 6780 | S30: 15020-AX5R-1440X300 | T30: F-A | V30: P | W30: 6,600 | X30: 滋賀 | Z30: 46191 | AA30: EC，検査 | AB30: ＊欠点個数確認チェック ラベル◎ 確認済み明記 6/23 1200m6/24 3600m6/25 1800m出荷可能 | AC30: 6/23 1200m6/24 3600m6/25 1800m出荷可能 | AF30: 共和天１ | AG30: 46196 | AH30: 46196 | AI30: 38 | AJ30: 186179T | AK30: 22 | AL30: 6 | AN30: 6600 | AO30: 38 | AP30: 250800 | AQ30: A2F20JXE4300FN1 | AR30: B2F20AXE4300FN1 | CF30: 受注ﾌｧｲﾙ | CG30: Sheet | CH30: FALSE
A31: 受注ﾌｧｲﾙ | B31: Y6-25 | C31: 通常入力 | D31: 後加工 | E31: 古家 | F31: 46211 | H31: 6713 | I31: 30033-BY00-640X200 | J31: F-A | K31: GA0 | L31: C | N31: 20000 | Q31: 1 | R31: 6710 | S31: 30066-AY00-640X200 | T31: F-A | U31: GA0 | V31: C | W31: 10,000 | X31: 滋賀 | Y31: ｽﾗｲｽ | Z31: 46210 | AA31: ｽﾗｲｽ | AC31: 検査前入庫依頼 | AE31: Y（工材） | AF31: 阿部加工 | AG31: 46217 | AH31: 46217 | AI31: 11 | AJ31: 186241M | AK31: 50 | AL31: 7 | AN31: 20000 | AO31: 11 | AP31: 220000 | AQ31: A2O33BY64200FG3 | AR31: B2O66AY64200FG3 | CF31: 受注ﾌｧｲﾙ | CG31: Sheet | CH31: FALSE
A32: 受注ﾌｧｲﾙ | B32: Y6-26 | C32: 通常入力 | D32: 後加工 | E32: 古家 | F32: 46211 | H32: 6713 | I32: 30033-BY00-640X200 | J32: F-A | K32: GA0 | L32: C | N32: 0 | Q32: 1 | R32: 6710 | S32: 30066-AY00-640X200 | T32: F-A | U32: GA0 | V32: C | W32: 0 | X32: 滋賀 | Y32: ｽﾗｲｽ | AA32: ｽﾗｲｽ | AB32: 国分工場へ | AC32: 検査前入庫依頼 | AE32: Y（工材） | AF32: 阿部加工 | AI32: 11 | AK32: 50 | AL32: 1 | AN32: 0 | AO32: 11 | AP32: 0 | AQ32: A2O33BY64200FG3 | AR32: B2O66AY64200FG3 | CF32: 受注ﾌｧｲﾙ | CG32: Sheet | CH32: FALSE
A33: 受注ﾌｧｲﾙ | B33: Y6-27 | C33: 通常入力 | D33: 後加工 | E33: 砂田 | F33: 46190 | H33: 6713 | I33: 30020-BG00-780X300 | J33: F-A | L33: V | N33: 22200 | Q33: 1 | R33: 6710 | S33: 30040-AG00-780X300 | T33: F-A | V33: C | W33: 11,100 | X33: 湖南 | Y33: ｽﾗｲｽ | Z33: 46191 | AA33: ｽﾗｲｽ | AB33: 3インチ紙管 | AE33: Y（工材） | AF33: 菅原電気 | AG33: 46197 | AH33: 46197 | AI33: 11 | AJ33: 186217T | AK33: 37 | AL33: 6 | AN33: 22200 | AO33: 11 | AP33: 244200 | AQ33: A2O20BG78300FN1 | AR33: B2O40AG78300FN1 | CF33: 受注ﾌｧｲﾙ | CG33: Sheet | CH33: FALSE
A34: 受注ﾌｧｲﾙ | B34: Y6-28 | C34: 通常入力 | D34: 後加工 | E34: 砂田 | F34: 46190 | H34: 6783 | I34: 30030-AP66-550X300 | J34: F-A | K34: BK0 | L34: M | N34: 0 | P34: 有 | Q34: 1 | R34: 6780 | S34: 30030-AP66-1110X300 | T34: F-A | U34: BK0 | V34: M | W34: 0 | X34: 湖南 | Y34: ｽﾘｯﾄ | Z34: 46204 | AA34: ｽﾘｯﾄ，欠点表示 | AB34: スリットした側にもラベル貼付 | AC34: 検査前入庫依頼 | AE34: Y（工材） | AF34: ｺﾞﾄｰﾌﾟﾗｽﾁｯｸ | AG34: 46206 | AH34: 46206 | AI34: 21.5 | AK34: 15 | AL34: 7 | AN34: 0 | AO34: 21.5 | AP34: 0 | AQ34: A2O30AP55300FB4 | AR34: B2O30APB0300FB4 | CF34: 受注ﾌｧｲﾙ | CG34: Sheet | CH34: FALSE
A35: 受注ﾌｧｲﾙ | B35: T6-20 | C35: 通常入力 | D35: 後加工 | E35: 古家 | F35: 46184 | H35: 6713 | I35: 30030-JG20-1050X200 | J35: F-A | K35: GA0 | L35: Q | N35: 1600 | O35: Ｑ面 | Q35: 1 | R35: 6710 | S35: 30030-AG20-1050X200 | T35: F-A | U35: GA0 | V35: U | W35: 1,600 | X35: 滋賀 | Y35: EC | Z35: 46188 | AA35: EC | AE35: Y（工材） | AF35: 中央物産 | AG35: 46195 | AH35: 46195 | AI35: 18 | AJ35: 185821Z | AK35: 8 | AL35: 6 | AN35: 1600 | AO35: 18 | AP35: 28800 | AQ35: A2O30JGA5200F35 | AR35: B2O30AGA5200FG3 | CF35: 受注ﾌｧｲﾙ | CG35: Sheet | CH35: FALSE
A36: 受注ﾌｧｲﾙ | B36: T6-21 | C36: 通常入力 | D36: 後加工 | E36: 古家 | F36: 46184 | H36: 6713 | I36: 10010-FY00-740X200 | J36: F-A | K36: GR0 | L36: C | N36: 400 | Q36: 1 | R36: 6710 | S36: 10010-AY00-750X200 | T36: F-A | U36: GR0 | V36: C | W36: 400 | X36: 湖南 | Y36: ｴﾝﾎﾞｽ | Z36: 46191 | AA36: エンボス | AE36: Y（工材） | AF36: ニックス | AG36: 46198 | AH36: 46198 | AI36: 17 | AJ36: 185817Y | AK36: 2 | AL36: 6 | AN36: 400 | AO36: 17 | AP36: 6800 | AQ36: A2A10FY74200FG6 | AR36: B2A10AY75200FG6 | CF36: 受注ﾌｧｲﾙ | CG36: Sheet | CH36: FALSE
A37: 受注ﾌｧｲﾙ | B37: JR260604-1 | C37: 通常入力 | D37: TPI | E37: 古家 | F37: 46184 | I37: 40040-R10W-870X95 | J37: F-A | N37: 190 | Q37: 1 | R37: 7A1 | S37: FEL4004AY-10WD-1000X100 | T37: F-A | W37: 200 | X37: 湖南 | Y37: 融着 | Z37: 46183 | AA37: 熱融着 | AE37: JR（屋根） | AF37: 小口加工 | AG37: 46195 | AH37: 46195 | AK37: 2 | AL37: 6 | AN37: 190 | AP37: 0 | AQ37: A3P40R187095F51 | AR37: B3P404AA0100FA1 | CF37: 受注ﾌｧｲﾙ | CG37: Sheet | CH37: FALSE
A38: 受注ﾌｧｲﾙ | B38: W6-15 | C38: 通常入力 | D38: 後加工 | E38: 古家 | F38: 46184 | H38: 6783 | I38: 30030-JP66-1300X200 | J38: F-A | L38: Q | N38: 400 | O38: Ｑ面 | Q38: 1 | R38: 6780 | S38: 30030-AP66-1300X200 | T38: F-A | V38: G | W38: 400 | X38: 滋賀 | Y38: EC | Z38: 46188 | AA38: EC,欠点表示 | AB38: ＊欠点個数確認チェック ラベル◎ H面マジックマーキングしてください Ｑ面にテープマーキングしてください | AE38: W（自動車） | AF38: 共和天１ | AG38: 46190 | AH38: 46190 | AI38: 31 | AJ38: 185822T | AK38: 2 | AL38: 6 | AN38: 400 | AO38: 31 | AP38: 12400 | AQ38: A2O30JPD0200FN1 | AR38: B2O30APD0200FN1 | CF38: 受注ﾌｧｲﾙ | CG38: Sheet | CH38: FALSE
A39: 受注ﾌｧｲﾙ | B39: W6-16 | C39: 通常入力 | D39: 後加工 | E39: 古家 | F39: 46184 | H39: 6783 | I39: 25025-JP17-1440X250 | J39: F-A | L39: Q | N39: 500 | O39: Ｑ面 | Q39: 1 | R39: 6780 | S39: 25025-AP17-1580X250 | T39: F-A | V39: P | W39: 500 | X39: 滋賀 | Y39: ｽﾘｯﾄ | Z39: 46188 | AA39: EC,ｽﾘｯﾄ | AB39: ＊欠点個数確認チェック ラベル◎ | AE39: W（自動車） | AF39: 共和天１ | AG39: 46190 | AH39: 46190 | AI39: 35 | AJ39: 185823P | AK39: 2 | AL39: 6 | AN39: 500 | AO39: 35 | AP39: 17500 | AQ39: A2N25JPE4250FN1 | AR39: B2N25APF8250FN1 | CF39: 受注ﾌｧｲﾙ | CG39: Sheet | CH39: FALSE
A40: 受注ﾌｧｲﾙ | B40: W6-17 | C40: 通常入力 | D40: 後加工 | E40: 古家 | F40: 46184 | H40: 6783 6783 6783 | I40: 15015-AP67-1310X60 15015-AP67-950X60 15015-AP67-1550X | J40: F-A F-A F-A | L40: P P P | N40: 60 60 | P40: 有 有 | Q40: 1 | R40: 6783 | S40: 15015-AP67-1550X317 | T40: F-A | V40: P | W40: 317 | X40: 湖南 | Y40: ｽﾘｯﾄ | Z40: 46188 | AA40: スリット、分割 | AE40: W（自動車） | AF40: 共和新城 | AG40: 46190 | AH40: 46190 | AI40: 32 | AJ40: 185858J 185859A | AK40: 1 | AL40: 6 | AN40: 60 60 | AO40: 32 | AP40: 3840 | AQ40: A2F15APD1100FN1 A2F15AP95100FN1 A2F15APF5190FN1 | AR40: B2F15APF5350FN1 | CF40: 受注ﾌｧｲﾙ | CG40: Sheet | CH40: FALSE
...

Sheet 呼び出された関数
A1: 依頼NO | B1: 項目 | C1: スライス | D1: EC | E1: スリット | F1: SEC | G1: 分割 | H1: 接続 | I1: 巻返し | J1: エンボス | K1: 欠点表示 | L1: 検査 | M1: --合計-- | N1: --計-- | O1: Column15 | P1: 年月 | Q1: 依頼NO(-1除外)
A2: C10-1 | B2: 加工金額 | C2: 198000 | D2: 0 | E2: 0 | F2: 0 | G2: 0 | H2: 0 | I2: 0 | J2: 0 | K2: 0 | L2: 0 | M2: 198000 | N2: 396000 | P2: 45931 | Q2: C10-1
A3: C10-10 | B3: 加工金額 | C3: 198000 | D3: 0 | E3: 0 | F3: 0 | G3: 0 | H3: 0 | I3: 0 | J3: 0 | K3: 0 | L3: 0 | M3: 198000 | N3: 396000 | P3: 45931 | Q3: C10-10
A4: C10-11 | B4: 加工金額 | C4: 0 | D4: 0 | E4: 40630 | F4: 62140 | G4: 0 | H4: 0 | I4: 0 | J4: 0 | K4: 0 | L4: 0 | M4: 102770 | N4: 205540 | P4: 45931 | Q4: C10-11
A5: C10-11-1 | B5: 加工金額 | C5: 0 | D5: 0 | E5: 6800 | F5: 10400 | G5: 0 | H5: 12000 | I5: 0 | J5: 0 | K5: 0 | L5: 0 | M5: 29200 | N5: 58400 | P5: 45931 | Q5: C10-11
A6: C10-12 | B6: 加工金額 | C6: 0 | D6: 0 | E6: 40800 | F6: 31200 | G6: 0 | H6: 0 | I6: 0 | J6: 0 | K6: 0 | L6: 0 | M6: 72000 | N6: 144000 | P6: 45931 | Q6: C10-12
A7: C10-13 | B7: 加工金額 | C7: 0 | D7: 0 | E7: 0 | F7: 213200 | G7: 0 | H7: 0 | I7: 0 | J7: 0 | K7: 0 | L7: 0 | M7: 213200 | N7: 426400 | P7: 45931 | Q7: C10-13
A8: C10-13-1 | B8: 加工金額 | C8: 0 | D8: 0 | E8: 0 | F8: 41600 | G8: 0 | H8: 48000 | I8: 0 | J8: 0 | K8: 0 | L8: 0 | M8: 89600 | N8: 179200 | P8: 45931 | Q8: C10-13
A9: C10-14 | B9: 加工金額 | C9: 0 | D9: 0 | E9: 0 | F9: 0 | G9: 0 | H9: 0 | I9: 0 | J9: 0 | K9: 0 | L9: 0 | M9: 0 | N9: 0 | P9: 45931 | Q9: C10-14
A10: C10-14-1 | B10: 加工金額 | C10: 0 | D10: 0 | E10: 0 | F10: 41600 | G10: 0 | H10: 48000 | I10: 0 | J10: 0 | K10: 0 | L10: 0 | M10: 89600 | N10: 179200 | P10: 45931 | Q10: C10-14
A11: C10-15 | B11: 加工金額 | C11: 0 | D11: 0 | E11: 81600 | F11: 62400 | G11: 0 | H11: 0 | I11: 0 | J11: 0 | K11: 0 | L11: 0 | M11: 144000 | N11: 288000 | P11: 45931 | Q11: C10-15
A12: C10-16 | B12: 加工金額 | C12: 0 | D12: 0 | E12: 13608 | F12: 31200 | G12: 0 | H12: 0 | I12: 0 | J12: 0 | K12: 0 | L12: 0 | M12: 44808 | N12: 89616 | P12: 45931 | Q12: C10-16
A13: C10-17 | B13: 加工金額 | C13: 0 | D13: 0 | E13: 34000 | F13: 26000 | G13: 0 | H13: 0 | I13: 0 | J13: 0 | K13: 0 | L13: 0 | M13: 60000 | N13: 120000 | P13: 45931 | Q13: C10-17
... A131: W9-22 | B131: 加工金額 | C131: 0 | D131: 10800 | E131: 0 | F131: 0 | G131: 0 | H131: 0 | I131: 0 | J131: 0 | K131: 0 | L131: 0 | M131: 10800 | N131: 21600 | P131: 45931 | Q131: W9-22

Sheet 月次実績表
A1: Date modified | B1: 依頼NO | C1: 依頼NO(-1除外) | D1: 項目 | E1: スライス | F1: EC | G1: スリット | H1: SEC | I1: 分割 | J1: 接続 | K1: 巻返し | L1: エンボス | M1: 改装 | N1: 欠点表示 | O1: 検査 | P1: 梱包 | Q1: --合計-- | R1: 年月 | S1: 依頼NO_年月
A2: 46260.665 | B2: C8-1 | C2: C8-1 | D2: 加工金額 | E2: 0 | F2: 0 | G2: 0 | H2: 207922 | I2: 0 | J2: 0 | K2: 0 | L2: 0 | M2: 0 | O2: 0 | P2: 0 | Q2: 207922 | R2: 46235 | S2: C8-1-202608
A3: 46260.665 | B3: C8-13 | C3: C8-13 | D3: 加工金額 | E3: 0 | F3: 0 | G3: 33507 | H3: 51246 | I3: 0 | J3: 0 | K3: 0 | L3: 0 | M3: 0 | O3: 0 | P3: 0 | Q3: 84753 | R3: 46235 | S3: C8-13-202608
A4: 46260.665 | B4: C8-14 | C4: C8-14 | D4: 加工金額 | E4: 0 | F4: 0 | G4: 6800 | H4: 5200 | I4: 0 | J4: 0 | K4: 0 | L4: 0 | M4: 0 | O4: 0 | P4: 0 | Q4: 12000 | R4: 46235 | S4: C8-14-202608
A5: 46260.665 | B5: C8-15 | C5: C8-15 | D5: 加工金額 | E5: 0 | F5: 0 | G5: 0 | H5: 104000 | I5: 0 | J5: 120000 | K5: 0 | L5: 0 | M5: 0 | O5: 0 | P5: 0 | Q5: 224000 | R5: 46235 | S5: C8-15-202608
A6: 46260.665 | B6: C8-16 | C6: C8-16 | D6: 加工金額 | E6: 0 | F6: 0 | G6: 0 | H6: 104000 | I6: 0 | J6: 0 | K6: 0 | L6: 0 | M6: 0 | O6: 0 | P6: 0 | Q6: 104000 | R6: 46235 | S6: C8-16-202608
A7: 46260.665 | B7: C8-17 | C7: C8-17 | D7: 加工金額 | E7: 0 | F7: 0 | G7: 0 | H7: 20800 | I7: 0 | J7: 24000 | K7: 0 | L7: 0 | M7: 0 | O7: 0 | P7: 0 | Q7: 44800 | R7: 46235 | S7: C8-17-202608
A8: 46260.665 | B8: C8-2 | C8: C8-2 | D8: 加工金額 | E8: 0 | F8: 0 | G8: 0 | H8: 130000 | I8: 0 | J8: 0 | K8: 0 | L8: 0 | M8: 0 | O8: 0 | P8: 0 | Q8: 130000 | R8: 46235 | S8: C8-2-202608
A9: 46260.665 | B9: C8-3 | C9: C8-3 | D9: 加工金額 | E9: 0 | F9: 0 | G9: 0 | H9: 254800 | I9: 0 | J9: 0 | K9: 0 | L9: 0 | M9: 0 | O9: 0 | P9: 0 | Q9: 254800 | R9: 46235 | S9: C8-3-202608
A10: 46260.665 | B10: C8-3-1 | C10: C8-3 | D10: 加工金額 | E10: 0 | F10: 0 | G10: 6800 | H10: 5200 | I10: 0 | J10: 0 | K10: 0 | L10: 0 | M10: 0 | O10: 0 | P10: 0 | Q10: 12000 | R10: 46235 | S10: C8-3-1-202608
A11: 46260.665 | B11: C8-4 | C11: C8-4 | D11: 加工金額 | E11: 0 | F11: 0 | G11: 0 | H11: 260000 | I11: 0 | J11: 0 | K11: 0 | L11: 0 | M11: 0 | O11: 0 | P11: 0 | Q11: 260000 | R11: 46235 | S11: C8-4-202608
A12: 46260.665 | B12: C8-5 | C12: C8-5 | D12: 加工金額 | E12: 0 | F12: 0 | G12: 0 | H12: 82862 | I12: 0 | J12: 0 | K12: 0 | L12: 0 | M12: 0 | O12: 0 | P12: 0 | Q12: 82862 | R12: 46235 | S12: C8-5-202608
A13: 46260.665 | B13: C8-6 | C13: C8-6 | D13: 加工金額 | E13: 4246 | F13: 0 | G13: 0 | H13: 0 | I13: 0 | J13: 0 | K13: 0 | L13: 0 | M13: 0 | O13: 0 | P13: 0 | Q13: 4246 | R13: 46235 | S13: C8-6-202608
... A64: 46260.665 | B64: PN08-05 | C64: PN08-05 | D64: 加工金額 | E64: 0 | F64: 36000 | G64: 0 | H64: 0 | I64: 0 | J64: 0 | K64: 0 | L64: 0 | M64: 0 | O64: 0 | P64: 3200 | Q64: 39200 | R64: 46235 | S64: PN08-05-202608
A65: 46268.397 | B65: C9-1 | C65: C9-1 | D65: 加工金額 | E65: 0 | F65: 0 | G65: 0 | H65: 220000 | K65: 0 | P65: 0 | Q65: 220000
A66: 46268.397 | B66: E9-1 | C66: E9-1 | D66: 加工金額 | E66: 0 | F66: 22500 | G66: 0 | H66: 0 | K66: 16250 | P66: 0 | Q66: 38750
A67: 46268.397 | B67: Y9-1 | C67: Y9-1 | D67: 加工金額 | E67: 54000 | F67: 0 | G67: 10500 | H67: 0 | K67: 0 | P67: 0 | Q67: 64500
A68: 46268.397 | B68: GB60802 | C68: GB60802 | D68: 加工金額 | E68: 9102 | F68: 0 | G68: 0 | H68: 0 | K68: 0 | P68: 0 | Q68: 9102
A69: 46268.397 | B69: GB60804 | C69: GB60804 | D69: 加工金額 | E69: 2275 | F69: 0 | G69: 0 | H69: 0 | K69: 0 | P69: 0 | Q69: 2275
A70: 46268.397 | B70: JR260901 | C70: JR260901 | D70: 加工金額 | E70: 0 | F70: 0 | G70: 16150 | H70: 24700 | K70: 0 | P70: 1600 | Q70: 42450

Sheet 月次実績表_PIVOT
A1: 売上表 | R1: 構成比率
A2: 単位:千円 | H2: * | J2: * | L2: * | M2: * | N2: ↓*印の合計 | Y2: * | AA2: * | AC2: * | AD2: *
A3: 年月 | B3: _スライス | C3: _EC | D3: _スリット | E3: _SEC | F3: _分割 | G3: _接続 | H3: _巻返し | I3: _エンボス | J3: _改装 | K3: _欠点表示 | L3: _検査 | M3: _梱包 | N3: その他(*) | O3: 合計 | R3: 年月 | S3: _スライス | T3: _EC | U3: _スリット | V3: _SEC | W3: _分割 | X3: _接続 | Y3: _巻返し | Z3: _エンボス | AA3: _改装 | AB3: _欠点表示 | AC3: _検査 | AD3: _梱包 | AE3: その他(*)
A4: 46235 | B4: 64306 | C4: 1197648 | D4: 200562.95 | E4: 1346371 | F4: 78915 | G4: 233400.27 | H4: 3900 | I4: 95081 | J4: 6000 | L4: 996000 | M4: 18240 | N4: =H4+J4+L4+M4 -> 1024140 | O4: =SUM(B4:M4) -> 4240424.2 | R4: =A4 -> 46235 | S4: =B4/$O4 -> 0.015164992 | T4: =C4/$O4 -> 0.28243589 | U4: =D4/$O4 -> 0.04729785 | V4: =E4/$O4 -> 0.31750856 | W4: =F4/$O4 -> 0.018610166 | X4: =G4/$O4 -> 0.055041726 | Y4: =H4/$O4 -> 0.0009197193 | Z4: =I4/$O4 -> 0.022422521 | ... AE4: =N4/$O4 -> 0.24151829
N5: =H5+J5+L5+M5 -> 0 | O5: =SUM(B5:M5) -> 0 | R5: =A5 -> 0 | S5: =B5/$O5 -> #DIV/0! | T5: =C5/$O5 -> #DIV/0! | U5: =D5/$O5 -> #DIV/0! | V5: =E5/$O5 -> #DIV/0! | W5: =F5/$O5 -> #DIV/0! | X5: =G5/$O5 -> #DIV/0! | Y5: =H5/$O5 -> #DIV/0! | Z5: =I5/$O5 -> #DIV/0! | ... AE5: =N5/$O5 -> #DIV/0!
N6: =H6+J6+L6+M6 -> 0 | O6: =SUM(B6:M6) -> 0 | R6: =A6 -> 0 | S6: =B6/$O6 -> #DIV/0! | T6: =C6/$O6 -> #DIV/0! | U6: =D6/$O6 -> #DIV/0! | V6: =E6/$O6 -> #DIV/0! | W6: =F6/$O6 -> #DIV/0! | X6: =G6/$O6 -> #DIV/0! | Y6: =H6/$O6 -> #DIV/0! | Z6: =I6/$O6 -> #DIV/0! | ... AE6: =N6/$O6 -> #DIV/0!
N7: =H7+J7+L7+M7 -> 0 | O7: =SUM(B7:M7) -> 0 | R7: =A7 -> 0 | S7: =B7/$O7 -> #DIV/0! | T7: =C7/$O7 -> #DIV/0! | U7: =D7/$O7 -> #DIV/0! | V7: =E7/$O7 -> #DIV/0! | W7: =F7/$O7 -> #DIV/0! | X7: =G7/$O7 -> #DIV/0! | Y7: =H7/$O7 -> #DIV/0! | Z7: =I7/$O7 -> #DIV/0! | ... AE7: =N7/$O7 -> #DIV/0!
N8: =H8+J8+L8+M8 -> 0 | O8: =SUM(B8:M8) -> 0 | R8: =A8 -> 0 | S8: =B8/$O8 -> #DIV/0! | T8: =C8/$O8 -> #DIV/0! | U8: =D8/$O8 -> #DIV/0! | V8: =E8/$O8 -> #DIV/0! | W8: =F8/$O8 -> #DIV/0! | X8: =G8/$O8 -> #DIV/0! | Y8: =H8/$O8 -> #DIV/0! | Z8: =I8/$O8 -> #DIV/0! | ... AE8: =N8/$O8 -> #DIV/0!
N9: =H9+J9+L9+M9 -> 0 | O9: =SUM(B9:M9) -> 0 | R9: =A9 -> 0 | S9: =B9/$O9 -> #DIV/0! | T9: =C9/$O9 -> #DIV/0! | U9: =D9/$O9 -> #DIV/0! | V9: =E9/$O9 -> #DIV/0! | W9: =F9/$O9 -> #DIV/0! | X9: =G9/$O9 -> #DIV/0! | Y9: =H9/$O9 -> #DIV/0! | Z9: =I9/$O9 -> #DIV/0! | ... AE9: =N9/$O9 -> #DIV/0!
N10: =H10+J10+L10+M10 -> 0 | O10: =SUM(B10:M10) -> 0 | R10: =A10 -> 0 | S10: =B10/$O10 -> #DIV/0! | T10: =C10/$O10 -> #DIV/0! | U10: =D10/$O10 -> #DIV/0! | V10: =E10/$O10 -> #DIV/0! | W10: =F10/$O10 -> #DIV/0! | X10: =G10/$O10 -> #DIV/0! | Y10: =H10/$O10 -> #DIV/0! | Z10: =I10/$O10 -> #DIV/0! | ... AE10: =N10/$O10 -> #DIV/0!
N11: =H11+J11+L11+M11 -> 0 | O11: =SUM(B11:M11) -> 0 | R11: =A11 -> 0 | S11: =B11/$O11 -> #DIV/0! | T11: =C11/$O11 -> #DIV/0! | U11: =D11/$O11 -> #DIV/0! | V11: =E11/$O11 -> #DIV/0! | W11: =F11/$O11 -> #DIV/0! | X11: =G11/$O11 -> #DIV/0! | Y11: =H11/$O11 -> #DIV/0! | Z11: =I11/$O11 -> #DIV/0! | ... AE11: =N11/$O11 -> #DIV/0!
N12: =H12+J12+L12+M12 -> 0 | O12: =SUM(B12:M12) -> 0 | R12: =A12 -> 0 | S12: =B12/$O12 -> #DIV/0! | T12: =C12/$O12 -> #DIV/0! | U12: =D12/$O12 -> #DIV/0! | V12: =E12/$O12 -> #DIV/0! | W12: =F12/$O12 -> #DIV/0! | X12: =G12/$O12 -> #DIV/0! | Y12: =H12/$O12 -> #DIV/0! | Z12: =I12/$O12 -> #DIV/0! | ... AE12: =N12/$O12 -> #DIV/0!
N13: =H13+J13+L13+M13 -> 0 | O13: =SUM(B13:M13) -> 0 | R13: =A13 -> 0 | S13: =B13/$O13 -> #DIV/0! | T13: =C13/$O13 -> #DIV/0! | U13: =D13/$O13 -> #DIV/0! | V13: =E13/$O13 -> #DIV/0! | W13: =F13/$O13 -> #DIV/0! | X13: =G13/$O13 -> #DIV/0! | Y13: =H13/$O13 -> #DIV/0! | Z13: =I13/$O13 -> #DIV/0! | ... AE13: =N13/$O13 -> #DIV/0!
N14: =H14+J14+L14+M14 -> 0 | O14: =SUM(B14:M14) -> 0 | R14: =A14 -> 0 | S14: =B14/$O14 -> #DIV/0! | T14: =C14/$O14 -> #DIV/0! | U14: =D14/$O14 -> #DIV/0! | V14: =E14/$O14 -> #DIV/0! | W14: =F14/$O14 -> #DIV/0! | X14: =G14/$O14 -> #DIV/0! | Y14: =H14/$O14 -> #DIV/0! | Z14: =I14/$O14 -> #DIV/0! | ... AE14: =N14/$O14 -> #DIV/0!
N15: =H15+J15+L15+M15 -> 0 | O15: =SUM(B15:M15) -> 0 | R15: =A15 -> 0 | S15: =B15/$O15 -> #DIV/0! | T15: =C15/$O15 -> #DIV/0! | U15: =D15/$O15 -> #DIV/0! | V15: =E15/$O15 -> #DIV/0! | W15: =F15/$O15 -> #DIV/0! | X15: =G15/$O15 -> #DIV/0! | Y15: =H15/$O15 -> #DIV/0! | Z15: =I15/$O15 -> #DIV/0! | ... AE15: =N15/$O15 -> #DIV/0!
N16: =H16+J16+L16+M16 -> 0 | O16: =SUM(B16:M16) -> 0 | R16: =A16 -> 0 | S16: =B16/$O16 -> #DIV/0! | T16: =C16/$O16 -> #DIV/0! | U16: =D16/$O16 -> #DIV/0! | V16: =E16/$O16 -> #DIV/0! | W16: =F16/$O16 -> #DIV/0! | X16: =G16/$O16 -> #DIV/0! | Y16: =H16/$O16 -> #DIV/0! | Z16: =I16/$O16 -> #DIV/0! | ... AE16: =N16/$O16 -> #DIV/0!
N17: =H17+J17+L17+M17 -> 0 | O17: =SUM(B17:M17) -> 0 | R17: =A17 -> 0 | S17: =B17/$O17 -> #DIV/0! | T17: =C17/$O17 -> #DIV/0! | U17: =D17/$O17 -> #DIV/0! | V17: =E17/$O17 -> #DIV/0! | W17: =F17/$O17 -> #DIV/0! | X17: =G17/$O17 -> #DIV/0! | Y17: =H17/$O17 -> #DIV/0! | Z17: =I17/$O17 -> #DIV/0! | ... AE17: =N17/$O17 -> #DIV/0!

Sheet _t受注ﾌｧｲﾙ_総合計
A1: 依頼Ｎｏ | B1: 加工内容 | C1: 調整納期 | D1: 受注数 | E1: 受注金額(修正) | F1: 加工完了日 | G1: 加工計画(完了日) | H1: 集計日 | I1: 加工金額合計(月次実績) | J1: 加工金額 | K1: 加工完了金額 | L1: TPI2 | M1: 東レ | N1: 工程1 | O1: 工程2 | P1: 工程3 | Q1: 工程4 | R1: 工程5
A2: W7-4 | B2: EC,検査 | C2: 46225 | D2: 1200 | E2: 45600 | F2: {=_xlfn.LET( _xlpm._完了日,_加工実績DATA[加工完了日], _xlpm._調整納期列,_t受注ﾌｧｲﾙ_総合計[調整納期], _xlpm._加工完了日,_xlfn.TAKE( _xlfn._xlws.FILTER(_xlpm._完了日, (A2=_加工実績DATA[依頼NO])* (YEAR(C2) = YEAR(_xlpm._完了日)) ),1), IF(_xlpm._加工完了日 = 0,NA(),_xlpm._加工完了日) )} -> 46227 | G2: {=_xlfn.LET( _xlpm._完了日列,#REF!, _xlpm._完了日, _xlfn.TAKE( _xlfn._xlws.FILTER(_xlpm._完了日列, (A2=#REF!)* (DATEVALUE("2025/1/1") < C2) ),1 ), IFERROR(_xlpm._完了日,"") )} | H2: {=_xlfn.LET( _xlpm.f, IFERROR(F2, 0), _xlpm.g, IFERROR(G2, 0), _xlpm.c, IFERROR(C2, 0), _xlfn.IFS( ISNUMBER(_xlpm.f)*(_xlpm.f>0), _xlpm.f, ISNUMBER(_xlpm.g)*(_xlpm.g>0), _xlpm.g, ISNUMBER(_xlpm.c)*(_xlpm.c>0), _xlpm.c, TRUE, "" ) )} -> 46227 | I2: {=_xlfn.LET( _xlpm._加工金額合計列,_t月次実績表[--合計--], _xlpm._月次年月日列,_t月次実績表[年月], _xlpm._依頼NO列,_t月次実績表[依頼NO(-1除外)], IFERROR( SUM( _xlfn._xlws.FILTER(_xlpm._加工金額合計列, (A2=_xlpm._依頼NO列) * (YEAR(_xlpm._月次年月日列) = YEAR(H2)) ) ), 0) )} -> 0 | J2: =IFERROR( IF( _t受注ﾌｧｲﾙ_総合計[[#This Row],[受注金額(修正)]] > _t受注ﾌｧｲﾙ_総合計[[#This Row],[加工金額合計(月次実績)]], _t受注ﾌｧｲﾙ_総合計[[#This Row],[受注金額(修正)]], _t受注ﾌｧｲﾙ_総合計[[#This Row],[加工金額合計(月次実績)]] ), 0 ) -> 45600 | K2: =IF(ISERROR(F2),0,E2) -> 45600 | L2: =_xlfn.LET( _xlpm._依頼NO, A2, _xlpm._集計年, YEAR(H2), _xlpm._依頼列, _t受注ﾌｧｲﾙ_TPI[依頼Ｎｏ], _xlpm._集計日列, _t受注ﾌｧｲﾙ_TPI[集計日], COUNTIFS( _xlpm._依頼列, _xlpm._依頼NO, _xlpm._集計日列, ">=" & DATE(_xlpm._集計年,1,1), _xlpm._集計日列, "<" & DATE(_xlpm._集計年+1,1,1) ) ) -> 0 | M2: =_xlfn.LET( _xlpm._依頼NO, A2, _xlpm._集計年, YEAR(H2), _xlpm._依頼列,_t受注ﾌｧｲﾙ_東レ[依頼Ｎｏ], _xlpm._集計日列, _t受注ﾌｧｲﾙ_東レ[集計日], COUNTIFS( _xlpm._依頼列, _xlpm._依頼NO, _xlpm._集計日列, ">=" & DATE(_xlpm._集計年,1,1), _xlpm._集計日列, "<" & DATE(_xlpm._集計年+1,1,1) ) ) -> 1 | N2: =IFERROR( INDEX( _xlfn.TEXTSPLIT( SUBSTITUTE(SUBSTITUTE(B2, "，", ","), "、", ","), ",", ), 1, 1 ), "" ) -> EC | O2: =IFERROR( INDEX( _xlfn.TEXTSPLIT( SUBSTITUTE(SUBSTITUTE(B2, "，", ","), "、", ","), ",", ), 1, 2 ), "" ) -> 検査 | P2: =IFERROR( INDEX( _xlfn.TEXTSPLIT( SUBSTITUTE(SUBSTITUTE(B2, "，", ","), "、", ","), ",", ), 1, 3 ), "" ) | Q2: =IFERROR( INDEX( _xlfn.TEXTSPLIT( SUBSTITUTE(SUBSTITUTE(B2, "，", ","), "、", ","), ",", ), 1, 4 ), "" ) | R2: =IFERROR( INDEX( _xlfn.TEXTSPLIT( SUBSTITUTE(SUBSTITUTE(B2, "，", ","), "、", ","), ",", ), 1, 5 ), "" )
A3: W7-5 | B3: EC,検査 | C3: 46221 | D3: 3300 | E3: 125400 | F3: {=_xlfn.LET( _xlpm._完了日,_加工実績DATA[加工完了日], _xlpm._調整納期列,_t受注ﾌｧｲﾙ_総合計[調整納期], _xlpm._加工完了日,_xlfn.TAKE( _xlfn._xlws.FILTER(_xlpm._完了日, (A3=_加工実績DATA[依頼NO])* (YEAR(C3) = YEAR(_xlpm._完了日)) ),1), IF(_xlpm._加工完了日 = 0,NA(),_xlpm._加工完了日) )} -> 46227 | G3: {=_xlfn.LET( _xlpm._完了日列,#REF!, _xlpm._完了日, _xlfn.TAKE( _xlfn._xlws.FILTER(_xlpm._完了日列, (A3=#REF!)* (DATEVALUE("2025/1/1") < C3) ),1 ), IFERROR(_xlpm._完了日,"") )} | H3: {=_xlfn.LET( _xlpm.f, IFERROR(F3, 0), _xlpm.g, IFERROR(G3, 0), _xlpm.c, IFERROR(C3, 0), _xlfn.IFS( ISNUMBER(_xlpm.f)*(_xlpm.f>0), _xlpm.f, ISNUMBER(_xlpm.g)*(_xlpm.g>0), _xlpm.g, ISNUMBER(_xlpm.c)*(_xlpm.c>0), _xlpm.c, TRUE, "" ) )} -> 46227 | I3: {=_xlfn.LET( _xlpm._加工金額合計列,_t月次実績表[--合計--], _xlpm._月次年月日列,_t月次実績表[年月], _xlpm._依頼NO列,_t月次実績表[依頼NO(-1除外)], IFERROR( SUM( _xlfn._xlws.FILTER(_xlpm._加工金額合計列, (A3=_xlpm._依頼NO列) * (YEAR(_xlpm._月次年月日列) = YEAR(H3)) ) ), 0) )} -> 0 | J3: =IFERROR( IF( _t受注ﾌｧｲﾙ_総合計[[#This Row],[受注金額(修正)]] > _t受注ﾌｧｲﾙ_総合計[[#This Row],[加工金額合計(月次実績)]], _t受注ﾌｧｲﾙ_総合計[[#This Row],[受注金額(修正)]], _t受注ﾌｧｲﾙ_総合計[[#This Row],[加工金額合計(月次実績)]] ), 0 ) -> 125400 | K3: =IF(ISERROR(F3),0,E3) -> 125400 | L3: =_xlfn.LET( _xlpm._依頼NO, A3, _xlpm._集計年, YEAR(H3), _xlpm._依頼列, _t受注ﾌｧｲﾙ_TPI[依頼Ｎｏ], _xlpm._集計日列, _t受注ﾌｧｲﾙ_TPI[集計日], COUNTIFS( _xlpm._依頼列, _xlpm._依頼NO, _xlpm._集計日列, ">=" & DATE(_xlpm._集計年,1,1), _xlpm._集計日列, "<" & DATE(_xlpm._集計年+1,1,1) ) ) -> 0 | M3: =_xlfn.LET( _xlpm._依頼NO, A3, _xlpm._集計年, YEAR(H3), _xlpm._依頼列,_t受注ﾌｧｲﾙ_東レ[依頼Ｎｏ], _xlpm._集計日列, _t受注ﾌｧｲﾙ_東レ[集計日], COUNTIFS( _xlpm._依頼列, _xlpm._依頼NO, _xlpm._集計日列, ">=" & DATE(_xlpm._集計年,1,1), _xlpm._集計日列, "<" & DATE(_xlpm._集計年+1,1,1) ) ) -> 1 | N3: =IFERROR( INDEX( _xlfn.TEXTSPLIT( SUBSTITUTE(SUBSTITUTE(B3, "，", ","), "、", ","), ",", ), 1, 1 ), "" ) -> EC | O3: =IFERROR( INDEX( _xlfn.TEXTSPLIT( SUBSTITUTE(SUBSTITUTE(B3, "，", ","), "、", ","), ",", ), 1, 2 ), "" ) -> 検査 | P3: =IFERROR( INDEX( _xlfn.TEXTSPLIT( SUBSTITUTE(SUBSTITUTE(B3, "，", ","), "、", ","), ",", ), 1, 3 ), "" ) | Q3: =IFERROR( INDEX( _xlfn.TEXTSPLIT( SUBSTITUTE(SUBSTITUTE(B3, "，", ","), "、", ","), ",", ), 1, 4 ), "" ) | R3: =IFERROR( INDEX( _xlfn.TEXTSPLIT( SUBSTITUTE(SUBSTITUTE(B3, "，", ","), "、", ","), ",", ), 1, 5 ), "" )
A4: JR260701 | B4: SEC,ｽﾘｯﾄ | C4: 46211 | D4: 1940 | E4: 83420 | F4: {=_xlfn.LET( _xlpm._完了日,_加工実績DATA[加工完了日], _xlpm._調整納期列,_t受注ﾌｧｲﾙ_総合計[調整納期], _xlpm._加工完了日,_xlfn.TAKE( _xlfn._xlws.FILTER(_xlpm._完了日, (A4=_加工実績DATA[依頼NO])* (YEAR(C4) = YEAR(_xlpm._完了日)) ),1), IF(_xlpm._加工完了日 = 0,NA(),_xlpm._加工完了日) )} -> 46206 | G4: {=_xlfn.LET( _xlpm._完了日列,#REF!, _xlpm._完了日, _xlfn.TAKE( _xlfn._xlws.FILTER(_xlpm._完了日列, (A4=#REF!)* (DATEVALUE("2025/1/1") < C4) ),1 ), IFERROR(_xlpm._完了日,"") )} | H4: {=_xlfn.LET( _xlpm.f, IFERROR(F4, 0), _xlpm.g, IFERROR(G4, 0), _xlpm.c, IFERROR(C4, 0), _xlfn.IFS( ISNUMBER(_xlpm.f)*(_xlpm.f>0), _xlpm.f, ISNUMBER(_xlpm.g)*(_xlpm.g>0), _xlpm.g, ISNUMBER(_xlpm.c)*(_xlpm.c>0), _xlpm.c, TRUE, "" ) )} -> 46206 | I4: {=_xlfn.LET( _xlpm._加工金額合計列,_t月次実績表[--合計--], _xlpm._月次年月日列,_t月次実績表[年月], _xlpm._依頼NO列,_t月次実績表[依頼NO(-1除外)], IFERROR( SUM( _xlfn._xlws.FILTER(_xlpm._加工金額合計列, (A4=_xlpm._依頼NO列) * (YEAR(_xlpm._月次年月日列) = YEAR(H4)) ) ), 0) )} -> 0 | J4: =IFERROR( IF( _t受注ﾌｧｲﾙ_総合計[[#This Row],[受注金額(修正)]] > _t受注ﾌｧｲﾙ_総合計[[#This Row],[加工金額合計(月次実績)]], _t受注ﾌｧｲﾙ_総合計[[#This Row],[受注金額(修正)]], _t受注ﾌｧｲﾙ_総合計[[#This Row],[加工金額合計(月次実績)]] ), 0 ) -> 83420 | K4: =IF(ISERROR(F4),0,E4) -> 83420 | L4: =_xlfn.LET( _xlpm._依頼NO, A4, _xlpm._集計年, YEAR(H4), _xlpm._依頼列, _t受注ﾌｧｲﾙ_TPI[依頼Ｎｏ], _xlpm._集計日列, _t受注ﾌｧｲﾙ_TPI[集計日], COUNTIFS( _xlpm._依頼列, _xlpm._依頼NO, _xlpm._集計日列, ">=" & DATE(_xlpm._集計年,1,1), _xlpm._集計日列, "<" & DATE(_xlpm._集計年+1,1,1) ) ) -> 1 | M4: =_xlfn.LET( _xlpm._依頼NO, A4, _xlpm._集計年, YEAR(H4), _xlpm._依頼列,_t受注ﾌｧｲﾙ_東レ[依頼Ｎｏ], _xlpm._集計日列, _t受注ﾌｧｲﾙ_東レ[集計日], COUNTIFS( _xlpm._依頼列, _xlpm._依頼NO, _xlpm._集計日列, ">=" & DATE(_xlpm._集計年,1,1), _xlpm._集計日列, "<" & DATE(_xlpm._集計年+1,1,1) ) ) -> 0 | N4: =IFERROR( INDEX( _xlfn.TEXTSPLIT( SUBSTITUTE(SUBSTITUTE(B4, "，", ","), "、", ","), ",", ), 1, 1 ), "" ) -> SEC | O4: =IFERROR( INDEX( _xlfn.TEXTSPLIT( SUBSTITUTE(SUBSTITUTE(B4, "，", ","), "、", ","), ",", ), 1, 2 ), "" ) -> ｽﾘｯﾄ | P4: =IFERROR( INDEX( _xlfn.TEXTSPLIT( SUBSTITUTE(SUBSTITUTE(B4, "，", ","), "、", ","), ",", ), 1, 3 ), "" ) | Q4: =IFERROR( INDEX( _xlfn.TEXTSPLIT( SUBSTITUTE(SUBSTITUTE(B4, "，", ","), "、", ","), ",", ), 1, 4 ), "" ) | R4: =IFERROR( INDEX( _xlfn.TEXTSPLIT( SUBSTITUTE(SUBSTITUTE(B4, "，", ","), "、", ","), ",", ), 1, 5 ), "" )
A5: Y7-1 | B5: ｽﾗｲｽ | C5: 46212 | D5: 6000 | E5: 66000 | F5: {=_xlfn.LET( _xlpm._完了日,_加工実績DATA[加工完了日], _xlpm._調整納期列,_t受注ﾌｧｲﾙ_総合計[調整納期], _xlpm._加工完了日,_xlfn.TAKE( _xlfn._xlws.FILTER(_xlpm._完了日, (A5=_加工実績DATA[依頼NO])* (YEAR(C5) = YEAR(_xlpm._完了日)) ),1), IF(_xlpm._加工完了日 = 0,NA(),_xlpm._加工完了日) )} -> 46205 | G5: {=_xlfn.LET( _xlpm._完了日列,#REF!, _xlpm._完了日, _xlfn.TAKE( _xlfn._xlws.FILTER(_xlpm._完了日列, (A5=#REF!)* (DATEVALUE("2025/1/1") < C5) ),1 ), IFERROR(_xlpm._完了日,"") )} | H5: {=_xlfn.LET( _xlpm.f, IFERROR(F5, 0), _xlpm.g, IFERROR(G5, 0), _xlpm.c, IFERROR(C5, 0), _xlfn.IFS( ISNUMBER(_xlpm.f)*(_xlpm.f>0), _xlpm.f, ISNUMBER(_xlpm.g)*(_xlpm.g>0), _xlpm.g, ISNUMBER(_xlpm.c)*(_xlpm.c>0), _xlpm.c, TRUE, "" ) )} -> 46205 | I5: {=_xlfn.LET( _xlpm._加工金額合計列,_t月次実績表[--合計--], _xlpm._月次年月日列,_t月次実績表[年月], _xlpm._依頼NO列,_t月次実績表[依頼NO(-1除外)], IFERROR( SUM( _xlfn._xlws.FILTER(_xlpm._加工金額合計列, (A5=_xlpm._依頼NO列) * (YEAR(_xlpm._月次年月日列) = YEAR(H5)) ) ), 0) )} -> 0 | J5: =IFERROR( IF( _t受注ﾌｧｲﾙ_総合計[[#This Row],[受注金額(修正)]] > _t受注ﾌｧｲﾙ_総合計[[#This Row],[加工金額合計(月次実績)]], _t受注ﾌｧｲﾙ_総合計[[#This Row],[受注金額(修正)]], _t受注ﾌｧｲﾙ_総合計[[#This Row],[加工金額合計(月次実績)]] ), 0 ) -> 66000 | K5: =IF(ISERROR(F5),0,E5) -> 66000 | L5: =_xlfn.LET( _xlpm._依頼NO, A5, _xlpm._集計年, YEAR(H5), _xlpm._依頼列, _t受注ﾌｧｲﾙ_TPI[依頼Ｎｏ], _xlpm._集計日列, _t受注ﾌｧｲﾙ_TPI[集計日], COUNTIFS( _xlpm._依頼列, _xlpm._依頼NO, _xlpm._集計日列, ">=" & DATE(_xlpm._集計年,1,1), _xlpm._集計日列, "<" & DATE(_xlpm._集計年+1,1,1) ) ) -> 0 | M5: =_xlfn.LET( _xlpm._依頼NO, A5, _xlpm._集計年, YEAR(H5), _xlpm._依頼列,_t受注ﾌｧｲﾙ_東レ[依頼Ｎｏ], _xlpm._集計日列, _t受注ﾌｧｲﾙ_東レ[集計日], COUNTIFS( _xlpm._依頼列, _xlpm._依頼NO, _xlpm._集計日列, ">=" & DATE(_xlpm._集計年,1,1), _xlpm._集計日列, "<" & DATE(_xlpm._集計年+1,1,1) ) ) -> 1 | N5: =IFERROR( INDEX( _xlfn.TEXTSPLIT( SUBSTITUTE(SUBSTITUTE(B5, "，", ","), "、", ","), ",", ), 1, 1 ), "" ) -> ｽﾗｲｽ | O5: =IFERROR( INDEX( _xlfn.TEXTSPLIT( SUBSTITUTE(SUBSTITUTE(B5, "，", ","), "、", ","), ",", ), 1, 2 ), "" ) | P5: =IFERROR( INDEX( _xlfn.TEXTSPLIT( SUBSTITUTE(SUBSTITUTE(B5, "，", ","), "、", ","), ",", ), 1, 3 ), "" ) | Q5: =IFERROR( INDEX( _xlfn.TEXTSPLIT( SUBSTITUTE(SUBSTITUTE(B5, "，", ","), "、", ","), ",", ), 1, 4 ), "" ) | R5: =IFERROR( INDEX( _xlfn.TEXTSPLIT( SUBSTITUTE(SUBSTITUTE(B5, "，", ","), "、", ","), ",", ), 1, 5 ), "" )
A6: Y7-2 | B6: SEC,ｽﾘｯﾄ | C6: 46211 | D6: 1600 | E6: 16000 | F6: {=_xlfn.LET( _xlpm._完了日,_加工実績DATA[加工完了日], _xlpm._調整納期列,_t受注ﾌｧｲﾙ_総合計[調整納期], _xlpm._加工完了日,_xlfn.TAKE( _xlfn._xlws.FILTER(_xlpm._完了日, (A6=_加工実績DATA[依頼NO])* (YEAR(C6) = YEAR(_xlpm._完了日)) ),1), IF(_xlpm._加工完了日 = 0,NA(),_xlpm._加工完了日) )} -> 46209 | G6: {=_xlfn.LET( _xlpm._完了日列,#REF!, _xlpm._完了日, _xlfn.TAKE( _xlfn._xlws.FILTER(_xlpm._完了日列, (A6=#REF!)* (DATEVALUE("2025/1/1") < C6) ),1 ), IFERROR(_xlpm._完了日,"") )} | H6: {=_xlfn.LET( _xlpm.f, IFERROR(F6, 0), _xlpm.g, IFERROR(G6, 0), _xlpm.c, IFERROR(C6, 0), _xlfn.IFS( ISNUMBER(_xlpm.f)*(_xlpm.f>0), _xlpm.f, ISNUMBER(_xlpm.g)*(_xlpm.g>0), _xlpm.g, ISNUMBER(_xlpm.c)*(_xlpm.c>0), _xlpm.c, TRUE, "" ) )} -> 46209 | I6: {=_xlfn.LET( _xlpm._加工金額合計列,_t月次実績表[--合計--], _xlpm._月次年月日列,_t月次実績表[年月], _xlpm._依頼NO列,_t月次実績表[依頼NO(-1除外)], IFERROR( SUM( _xlfn._xlws.FILTER(_xlpm._加工金額合計列, (A6=_xlpm._依頼NO列) * (YEAR(_xlpm._月次年月日列) = YEAR(H6)) ) ), 0) )} -> 0 | J6: =IFERROR( IF( _t受注ﾌｧｲﾙ_総合計[[#This Row],[受注金額(修正)]] > _t受注ﾌｧｲﾙ_総合計[[#This Row],[加工金額合計(月次実績)]], _t受注ﾌｧｲﾙ_総合計[[#This Row],[受注金額(修正)]], _t受注ﾌｧｲﾙ_総合計[[#This Row],[加工金額合計(月次実績)]] ), 0 ) -> 16000 | K6: =IF(ISERROR(F6),0,E6) -> 16000 | L6: =_xlfn.LET( _xlpm._依頼NO, A6, _xlpm._集計年, YEAR(H6), _xlpm._依頼列, _t受注ﾌｧｲﾙ_TPI[依頼Ｎｏ], _xlpm._集計日列, _t受注ﾌｧｲﾙ_TPI[集計日], COUNTIFS( _xlpm._依頼列, _xlpm._依頼NO, _xlpm._集計日列, ">=" & DATE(_xlpm._集計年,1,1), _xlpm._集計日列, "<" & DATE(_xlpm._集計年+1,1,1) ) ) -> 0 | M6: =_xlfn.LET( _xlpm._依頼NO, A6, _xlpm._集計年, YEAR(H6), _xlpm._依頼列,_t受注ﾌｧｲﾙ_東レ[依頼Ｎｏ], _xlpm._集計日列, _t受注ﾌｧｲﾙ_東レ[集計日], COUNTIFS( _xlpm._依頼列, _xlpm._依頼NO, _xlpm._集計日列, ">=" & DATE(_xlpm._集計年,1,1), _xlpm._集計日列, "<" & DATE(_xlpm._集計年+1,1,1) ) ) -> 1 | N6: =IFERROR( INDEX( _xlfn.TEXTSPLIT( SUBSTITUTE(SUBSTITUTE(B6, "，", ","), "、", ","), ",", ), 1, 1 ), "" ) -> SEC | O6: =IFERROR( INDEX( _xlfn.TEXTSPLIT( SUBSTITUTE(SUBSTITUTE(B6, "，", ","), "、", ","), ",", ), 1, 2 ), "" ) -> ｽﾘｯﾄ | P6: =IFERROR( INDEX( _xlfn.TEXTSPLIT( SUBSTITUTE(SUBSTITUTE(B6, "，", ","), "、", ","), ",", ), 1, 3 ), "" ) | Q6: =IFERROR( INDEX( _xlfn.TEXTSPLIT( SUBSTITUTE(SUBSTITUTE(B6, "，", ","), "、", ","), ",", ), 1, 4 ), "" ) | R6: =IFERROR( INDEX( _xlfn.TEXTSPLIT( SUBSTITUTE(SUBSTITUTE(B6, "，", ","), "、", ","), ",", ), 1, 5 ), "" )
A7: Y7-3 | B7: SEC,ｽﾘｯﾄ | C7: 46211 | D7: 1200 | E7: 12000 | F7: {=_xlfn.LET( _xlpm._完了日,_加工実績DATA[加工完了日], _xlpm._調整納期列,_t受注ﾌｧｲﾙ_総合計[調整納期], _xlpm._加工完了日,_xlfn.TAKE( _xlfn._xlws.FILTER(_xlpm._完了日, (A7=_加工実績DATA[依頼NO])* (YEAR(C7) = YEAR(_xlpm._完了日)) ),1), IF(_xlpm._加工完了日 = 0,NA(),_xlpm._加工完了日) )} -> 46209 | G7: {=_xlfn.LET( _xlpm._完了日列,#REF!, _xlpm._完了日, _xlfn.TAKE( _xlfn._xlws.FILTER(_xlpm._完了日列, (A7=#REF!)* (DATEVALUE("2025/1/1") < C7) ),1 ), IFERROR(_xlpm._完了日,"") )} | H7: {=_xlfn.LET( _xlpm.f, IFERROR(F7, 0), _xlpm.g, IFERROR(G7, 0), _xlpm.c, IFERROR(C7, 0), _xlfn.IFS( ISNUMBER(_xlpm.f)*(_xlpm.f>0), _xlpm.f, ISNUMBER(_xlpm.g)*(_xlpm.g>0), _xlpm.g, ISNUMBER(_xlpm.c)*(_xlpm.c>0), _xlpm.c, TRUE, "" ) )} -> 46209 | I7: {=_xlfn.LET( _xlpm._加工金額合計列,_t月次実績表[--合計--], _xlpm._月次年月日列,_t月次実績表[年月], _xlpm._依頼NO列,_t月次実績表[依頼NO(-1除外)], IFERROR( SUM( _xlfn._xlws.FILTER(_xlpm._加工金額合計列, (A7=_xlpm._依頼NO列) * (YEAR(_xlpm._月次年月日列) = YEAR(H7)) ) ), 0) )} -> 0 | J7: =IFERROR( IF( _t受注ﾌｧｲﾙ_総合計[[#This Row],[受注金額(修正)]] > _t受注ﾌｧｲﾙ_総合計[[#This Row],[加工金額合計(月次実績)]], _t受注ﾌｧｲﾙ_総合計[[#This Row],[受注金額(修正)]], _t受注ﾌｧｲﾙ_総合計[[#This Row],[加工金額合計(月次実績)]] ), 0 ) -> 12000 | K7: =IF(ISERROR(F7),0,E7) -> 12000 | L7: =_xlfn.LET( _xlpm._依頼NO, A7, _xlpm._集計年, YEAR(H7), _xlpm._依頼列, _t受注ﾌｧｲﾙ_TPI[依頼Ｎｏ], _xlpm._集計日列, _t受注ﾌｧｲﾙ_TPI[集計日], COUNTIFS( _xlpm._依頼列, _xlpm._依頼NO, _xlpm._集計日列, ">=" & DATE(_xlpm._集計年,1,1), _xlpm._集計日列, "<" & DATE(_xlpm._集計年+1,1,1) ) ) -> 0 | M7: =_xlfn.LET( _xlpm._依頼NO, A7, _xlpm._集計年, YEAR(H7), _xlpm._依頼列,_t受注ﾌｧｲﾙ_東レ[依頼Ｎｏ], _xlpm._集計日列, _t受注ﾌｧｲﾙ_東レ[集計日], COUNTIFS( _xlpm._依頼列, _xlpm._依頼NO, _xlpm._集計日列, ">=" & DATE(_xlpm._集計年,1,1), _xlpm._集計日列, "<" & DATE(_xlpm._集計年+1,1,1) ) ) -> 1 | N7: =IFERROR( INDEX( _xlfn.TEXTSPLIT( SUBSTITUTE(SUBSTITUTE(B7, "，", ","), "、", ","), ",", ), 1, 1 ), "" ) -> SEC | O7: =IFERROR( INDEX( _xlfn.TEXTSPLIT( SUBSTITUTE(SUBSTITUTE(B7, "，", ","), "、", ","), ",", ), 1, 2 ), "" ) -> ｽﾘｯﾄ | P7: =IFERROR( INDEX( _xlfn.TEXTSPLIT( SUBSTITUTE(SUBSTITUTE(B7, "，", ","), "、", ","), ",", ), 1, 3 ), "" ) | Q7: =IFERROR( INDEX( _xlfn.TEXTSPLIT( SUBSTITUTE(SUBSTITUTE(B7, "，", ","), "、", ","), ",", ), 1, 4 ), "" ) | R7: =IFERROR( INDEX( _xlfn.TEXTSPLIT( SUBSTITUTE(SUBSTITUTE(B7, "，", ","), "、", ","), ",", ), 1, 5 ), "" )
A8: V6-16 | B8: ｽﾗｲｽ，巻き返し | C8: 46192 | D8: 100 | E8: 3500 | F8: {=_xlfn.LET( _xlpm._完了日,_加工実績DATA[加工完了日], _xlpm._調整納期列,_t受注ﾌｧｲﾙ_総合計[調整納期], _xlpm._加工完了日,_xlfn.TAKE( _xlfn._xlws.FILTER(_xlpm._完了日, (A8=_加工実績DATA[依頼NO])* (YEAR(C8) = YEAR(_xlpm._完了日)) ),1), IF(_xlpm._加工完了日 = 0,NA(),_xlpm._加工完了日) )} -> 46196 | G8: {=_xlfn.LET( _xlpm._完了日列,#REF!, _xlpm._完了日, _xlfn.TAKE( _xlfn._xlws.FILTER(_xlpm._完了日列, (A8=#REF!)* (DATEVALUE("2025/1/1") < C8) ),1 ), IFERROR(_xlpm._完了日,"") )} | H8: {=_xlfn.LET( _xlpm.f, IFERROR(F8, 0), _xlpm.g, IFERROR(G8, 0), _xlpm.c, IFERROR(C8, 0), _xlfn.IFS( ISNUMBER(_xlpm.f)*(_xlpm.f>0), _xlpm.f, ISNUMBER(_xlpm.g)*(_xlpm.g>0), _xlpm.g, ISNUMBER(_xlpm.c)*(_xlpm.c>0), _xlpm.c, TRUE, "" ) )} -> 46196 | I8: {=_xlfn.LET( _xlpm._加工金額合計列,_t月次実績表[--合計--], _xlpm._月次年月日列,_t月次実績表[年月], _xlpm._依頼NO列,_t月次実績表[依頼NO(-1除外)], IFERROR( SUM( _xlfn._xlws.FILTER(_xlpm._加工金額合計列, (A8=_xlpm._依頼NO列) * (YEAR(_xlpm._月次年月日列) = YEAR(H8)) ) ), 0) )} -> 0 | J8: =IFERROR( IF( _t受注ﾌｧｲﾙ_総合計[[#This Row],[受注金額(修正)]] > _t受注ﾌｧｲﾙ_総合計[[#This Row],[加工金額合計(月次実績)]], _t受注ﾌｧｲﾙ_総合計[[#This Row],[受注金額(修正)]], _t受注ﾌｧｲﾙ_総合計[[#This Row],[加工金額合計(月次実績)]] ), 0 ) -> 3500 | K8: =IF(ISERROR(F8),0,E8) -> 3500 | L8: =_xlfn.LET( _xlpm._依頼NO, A8, _xlpm._集計年, YEAR(H8), _xlpm._依頼列, _t受注ﾌｧｲﾙ_TPI[依頼Ｎｏ], _xlpm._集計日列, _t受注ﾌｧｲﾙ_TPI[集計日], COUNTIFS( _xlpm._依頼列, _xlpm._依頼NO, _xlpm._集計日列, ">=" & DATE(_xlpm._集計年,1,1), _xlpm._集計日列, "<" & DATE(_xlpm._集計年+1,1,1) ) ) -> 0 | M8: =_xlfn.LET( _xlpm._依頼NO, A8, _xlpm._集計年, YEAR(H8), _xlpm._依頼列,_t受注ﾌｧｲﾙ_東レ[依頼Ｎｏ], _xlpm._集計日列, _t受注ﾌｧｲﾙ_東レ[集計日], COUNTIFS( _xlpm._依頼列, _xlpm._依頼NO, _xlpm._集計日列, ">=" & DATE(_xlpm._集計年,1,1), _xlpm._集計日列, "<" & DATE(_xlpm._集計年+1,1,1) ) ) -> 1 | N8: =IFERROR( INDEX( _xlfn.TEXTSPLIT( SUBSTITUTE(SUBSTITUTE(B8, "，", ","), "、", ","), ",", ), 1, 1 ), "" ) -> ｽﾗｲｽ | O8: =IFERROR( INDEX( _xlfn.TEXTSPLIT( SUBSTITUTE(SUBSTITUTE(B8, "，", ","), "、", ","), ",", ), 1, 2 ), "" ) -> 巻き返し | P8: =IFERROR( INDEX( _xlfn.TEXTSPLIT( SUBSTITUTE(SUBSTITUTE(B8, "，", ","), "、", ","), ",", ), 1, 3 ), "" ) | Q8: =IFERROR( INDEX( _xlfn.TEXTSPLIT( SUBSTITUTE(SUBSTITUTE(B8, "，", ","), "、", ","), ",", ), 1, 4 ), "" ) | R8: =IFERROR( INDEX( _xlfn.TEXTSPLIT( SUBSTITUTE(SUBSTITUTE(B8, "，", ","), "、", ","), ",", ), 1, 5 ), "" ) | T8: =IF(_t受注ﾌｧｲﾙ_総合計[[#This Row],[加工金額]]=_t受注ﾌｧｲﾙ_総合計[[#This Row],[受注金額(修正)]],TRUE) -> TRUE
A9: W7-1 | B9: EC,ゴミ除去 | C9: 46212 | D9: 6000 | E9: 228000 | F9: {=_xlfn.LET( _xlpm._完了日,_加工実績DATA[加工完了日], _xlpm._調整納期列,_t受注ﾌｧｲﾙ_総合計[調整納期], _xlpm._加工完了日,_xlfn.TAKE( _xlfn._xlws.FILTER(_xlpm._完了日, (A9=_加工実績DATA[依頼NO])* (YEAR(C9) = YEAR(_xlpm._完了日)) ),1), IF(_xlpm._加工完了日 = 0,NA(),_xlpm._加工完了日) )} -> 46211 | G9: {=_xlfn.LET( _xlpm._完了日列,#REF!, _xlpm._完了日, _xlfn.TAKE( _xlfn._xlws.FILTER(_xlpm._完了日列, (A9=#REF!)* (DATEVALUE("2025/1/1") < C9) ),1 ), IFERROR(_xlpm._完了日,"") )} | H9: {=_xlfn.LET( _xlpm.f, IFERROR(F9, 0), _xlpm.g, IFERROR(G9, 0), _xlpm.c, IFERROR(C9, 0), _xlfn.IFS( ISNUMBER(_xlpm.f)*(_xlpm.f>0), _xlpm.f, ISNUMBER(_xlpm.g)*(_xlpm.g>0), _xlpm.g, ISNUMBER(_xlpm.c)*(_xlpm.c>0), _xlpm.c, TRUE, "" ) )} -> 46211 | I9: {=_xlfn.LET( _xlpm._加工金額合計列,_t月次実績表[--合計--], _xlpm._月次年月日列,_t月次実績表[年月], _xlpm._依頼NO列,_t月次実績表[依頼NO(-1除外)], IFERROR( SUM( _xlfn._xlws.FILTER(_xlpm._加工金額合計列, (A9=_xlpm._依頼NO列) * (YEAR(_xlpm._月次年月日列) = YEAR(H9)) ) ), 0) )} -> 0 | J9: =IFERROR( IF( _t受注ﾌｧｲﾙ_総合計[[#This Row],[受注金額(修正)]] > _t受注ﾌｧｲﾙ_総合計[[#This Row],[加工金額合計(月次実績)]], _t受注ﾌｧｲﾙ_総合計[[#This Row],[受注金額(修正)]], _t受注ﾌｧｲﾙ_総合計[[#This Row],[加工金額合計(月次実績)]] ), 0 ) -> 228000 | K9: =IF(ISERROR(F9),0,E9) -> 228000 | L9: =_xlfn.LET( _xlpm._依頼NO, A9, _xlpm._集計年, YEAR(H9), _xlpm._依頼列, _t受注ﾌｧｲﾙ_TPI[依頼Ｎｏ], _xlpm._集計日列, _t受注ﾌｧｲﾙ_TPI[集計日], COUNTIFS( _xlpm._依頼列, _xlpm._依頼NO, _xlpm._集計日列, ">=" & DATE(_xlpm._集計年,1,1), _xlpm._集計日列, "<" & DATE(_xlpm._集計年+1,1,1) ) ) -> 0 | M9: =_xlfn.LET( _xlpm._依頼NO, A9, _xlpm._集計年, YEAR(H9), _xlpm._依頼列,_t受注ﾌｧｲﾙ_東レ[依頼Ｎｏ], _xlpm._集計日列, _t受注ﾌｧｲﾙ_東レ[集計日], COUNTIFS( _xlpm._依頼列, _xlpm._依頼NO, _xlpm._集計日列, ">=" & DATE(_xlpm._集計年,1,1), _xlpm._集計日列, "<" & DATE(_xlpm._集計年+1,1,1) ) ) -> 1 | N9: =IFERROR( INDEX( _xlfn.TEXTSPLIT( SUBSTITUTE(SUBSTITUTE(B9, "，", ","), "、", ","), ",", ), 1, 1 ), "" ) -> EC | O9: =IFERROR( INDEX( _xlfn.TEXTSPLIT( SUBSTITUTE(SUBSTITUTE(B9, "，", ","), "、", ","), ",", ), 1, 2 ), "" ) -> ゴミ除去 | P9: =IFERROR( INDEX( _xlfn.TEXTSPLIT( SUBSTITUTE(SUBSTITUTE(B9, "，", ","), "、", ","), ",", ), 1, 3 ), "" ) | Q9: =IFERROR( INDEX( _xlfn.TEXTSPLIT( SUBSTITUTE(SUBSTITUTE(B9, "，", ","), "、", ","), ",", ), 1, 4 ), "" ) | R9: =IFERROR( INDEX( _xlfn.TEXTSPLIT( SUBSTITUTE(SUBSTITUTE(B9, "，", ","), "、", ","), ",", ), 1, 5 ), "" ) | T9: =IF(_t受注ﾌｧｲﾙ_総合計[[#This Row],[加工金額]]=_t受注ﾌｧｲﾙ_総合計[[#This Row],[受注金額(修正)]],TRUE) -> TRUE
A10: W7-2 | B10: EC,ゴミ除去 | C10: 46216 | D10: 6000 | E10: 228000 | F10: {=_xlfn.LET( _xlpm._完了日,_加工実績DATA[加工完了日], _xlpm._調整納期列,_t受注ﾌｧｲﾙ_総合計[調整納期], _xlpm._加工完了日,_xlfn.TAKE( _xlfn._xlws.FILTER(_xlpm._完了日, (A10=_加工実績DATA[依頼NO])* (YEAR(C10) = YEAR(_xlpm._完了日)) ),1), IF(_xlpm._加工完了日 = 0,NA(),_xlpm._加工完了日) )} -> 46213 | G10: {=_xlfn.LET( _xlpm._完了日列,#REF!, _xlpm._完了日, _xlfn.TAKE( _xlfn._xlws.FILTER(_xlpm._完了日列, (A10=#REF!)* (DATEVALUE("2025/1/1") < C10) ),1 ), IFERROR(_xlpm._完了日,"") )} | H10: {=_xlfn.LET( _xlpm.f, IFERROR(F10, 0), _xlpm.g, IFERROR(G10, 0), _xlpm.c, IFERROR(C10, 0), _xlfn.IFS( ISNUMBER(_xlpm.f)*(_xlpm.f>0), _xlpm.f, ISNUMBER(_xlpm.g)*(_xlpm.g>0), _xlpm.g, ISNUMBER(_xlpm.c)*(_xlpm.c>0), _xlpm.c, TRUE, "" ) )} -> 46213 | I10: {=_xlfn.LET( _xlpm._加工金額合計列,_t月次実績表[--合計--], _xlpm._月次年月日列,_t月次実績表[年月], _xlpm._依頼NO列,_t月次実績表[依頼NO(-1除外)], IFERROR( SUM( _xlfn._xlws.FILTER(_xlpm._加工金額合計列, (A10=_xlpm._依頼NO列) * (YEAR(_xlpm._月次年月日列) = YEAR(H10)) ) ), 0) )} -> 0 | J10: =IFERROR( IF( _t受注ﾌｧｲﾙ_総合計[[#This Row],[受注金額(修正)]] > _t受注ﾌｧｲﾙ_総合計[[#This Row],[加工金額合計(月次実績)]], _t受注ﾌｧｲﾙ_総合計[[#This Row],[受注金額(修正)]], _t受注ﾌｧｲﾙ_総合計[[#This Row],[加工金額合計(月次実績)]] ), 0 ) -> 228000 | K10: =IF(ISERROR(F10),0,E10) -> 228000 | L10: =_xlfn.LET( _xlpm._依頼NO, A10, _xlpm._集計年, YEAR(H10), _xlpm._依頼列, _t受注ﾌｧｲﾙ_TPI[依頼Ｎｏ], _xlpm._集計日列, _t受注ﾌｧｲﾙ_TPI[集計日], COUNTIFS( _xlpm._依頼列, _xlpm._依頼NO, _xlpm._集計日列, ">=" & DATE(_xlpm._集計年,1,1), _xlpm._集計日列, "<" & DATE(_xlpm._集計年+1,1,1) ) ) -> 0 | M10: =_xlfn.LET( _xlpm._依頼NO, A10, _xlpm._集計年, YEAR(H10), _xlpm._依頼列,_t受注ﾌｧｲﾙ_東レ[依頼Ｎｏ], _xlpm._集計日列, _t受注ﾌｧｲﾙ_東レ[集計日], COUNTIFS( _xlpm._依頼列, _xlpm._依頼NO, _xlpm._集計日列, ">=" & DATE(_xlpm._集計年,1,1), _xlpm._集計日列, "<" & DATE(_xlpm._集計年+1,1,1) ) ) -> 1 | N10: =IFERROR( INDEX( _xlfn.TEXTSPLIT( SUBSTITUTE(SUBSTITUTE(B10, "，", ","), "、", ","), ",", ), 1, 1 ), "" ) -> EC | O10: =IFERROR( INDEX( _xlfn.TEXTSPLIT( SUBSTITUTE(SUBSTITUTE(B10, "，", ","), "、", ","), ",", ), 1, 2 ), "" ) -> ゴミ除去 | P10: =IFERROR( INDEX( _xlfn.TEXTSPLIT( SUBSTITUTE(SUBSTITUTE(B10, "，", ","), "、", ","), ",", ), 1, 3 ), "" ) | Q10: =IFERROR( INDEX( _xlfn.TEXTSPLIT( SUBSTITUTE(SUBSTITUTE(B10, "，", ","), "、", ","), ",", ), 1, 4 ), "" ) | R10: =IFERROR( INDEX( _xlfn.TEXTSPLIT( SUBSTITUTE(SUBSTITUTE(B10, "，", ","), "、", ","), ",", ), 1, 5 ), "" ) | T10: =IF(_t受注ﾌｧｲﾙ_総合計[[#This Row],[加工金額]]=_t受注ﾌｧｲﾙ_総合計[[#This Row],[受注金額(修正)]],TRUE) -> TRUE
A11: W7-3 | B11: EC,ゴミ除去 | C11: 46217 | D11: 5400 | E11: 205200 | F11: {=_xlfn.LET( _xlpm._完了日,_加工実績DATA[加工完了日], _xlpm._調整納期列,_t受注ﾌｧｲﾙ_総合計[調整納期], _xlpm._加工完了日,_xlfn.TAKE( _xlfn._xlws.FILTER(_xlpm._完了日, (A11=_加工実績DATA[依頼NO])* (YEAR(C11) = YEAR(_xlpm._完了日)) ),1), IF(_xlpm._加工完了日 = 0,NA(),_xlpm._加工完了日) )} -> 46230 | G11: {=_xlfn.LET( _xlpm._完了日列,#REF!, _xlpm._完了日, _xlfn.TAKE( _xlfn._xlws.FILTER(_xlpm._完了日列, (A11=#REF!)* (DATEVALUE("2025/1/1") < C11) ),1 ), IFERROR(_xlpm._完了日,"") )} | H11: {=_xlfn.LET( _xlpm.f, IFERROR(F11, 0), _xlpm.g, IFERROR(G11, 0), _xlpm.c, IFERROR(C11, 0), _xlfn.IFS( ISNUMBER(_xlpm.f)*(_xlpm.f>0), _xlpm.f, ISNUMBER(_xlpm.g)*(_xlpm.g>0), _xlpm.g, ISNUMBER(_xlpm.c)*(_xlpm.c>0), _xlpm.c, TRUE, "" ) )} -> 46230 | I11: {=_xlfn.LET( _xlpm._加工金額合計列,_t月次実績表[--合計--], _xlpm._月次年月日列,_t月次実績表[年月], _xlpm._依頼NO列,_t月次実績表[依頼NO(-1除外)], IFERROR( SUM( _xlfn._xlws.FILTER(_xlpm._加工金額合計列, (A11=_xlpm._依頼NO列) * (YEAR(_xlpm._月次年月日列) = YEAR(H11)) ) ), 0) )} -> 0 | J11: =IFERROR( IF( _t受注ﾌｧｲﾙ_総合計[[#This Row],[受注金額(修正)]] > _t受注ﾌｧｲﾙ_総合計[[#This Row],[加工金額合計(月次実績)]], _t受注ﾌｧｲﾙ_総合計[[#This Row],[受注金額(修正)]], _t受注ﾌｧｲﾙ_総合計[[#This Row],[加工金額合計(月次実績)]] ), 0 ) -> 205200 | K11: =IF(ISERROR(F11),0,E11) -> 205200 | L11: =_xlfn.LET( _xlpm._依頼NO, A11, _xlpm._集計年, YEAR(H11), _xlpm._依頼列, _t受注ﾌｧｲﾙ_TPI[依頼Ｎｏ], _xlpm._集計日列, _t受注ﾌｧｲﾙ_TPI[集計日], COUNTIFS( _xlpm._依頼列, _xlpm._依頼NO, _xlpm._集計日列, ">=" & DATE(_xlpm._集計年,1,1), _xlpm._集計日列, "<" & DATE(_xlpm._集計年+1,1,1) ) ) -> 0 | M11: =_xlfn.LET( _xlpm._依頼NO, A11, _xlpm._集計年, YEAR(H11), _xlpm._依頼列,_t受注ﾌｧｲﾙ_東レ[依頼Ｎｏ], _xlpm._集計日列, _t受注ﾌｧｲﾙ_東レ[集計日], COUNTIFS( _xlpm._依頼列, _xlpm._依頼NO, _xlpm._集計日列, ">=" & DATE(_xlpm._集計年,1,1), _xlpm._集計日列, "<" & DATE(_xlpm._集計年+1,1,1) ) ) -> 1 | N11: =IFERROR( INDEX( _xlfn.TEXTSPLIT( SUBSTITUTE(SUBSTITUTE(B11, "，", ","), "、", ","), ",", ), 1, 1 ), "" ) -> EC | O11: =IFERROR( INDEX( _xlfn.TEXTSPLIT( SUBSTITUTE(SUBSTITUTE(B11, "，", ","), "、", ","), ",", ), 1, 2 ), "" ) -> ゴミ除去 | P11: =IFERROR( INDEX( _xlfn.TEXTSPLIT( SUBSTITUTE(SUBSTITUTE(B11, "，", ","), "、", ","), ",", ), 1, 3 ), "" ) | Q11: =IFERROR( INDEX( _xlfn.TEXTSPLIT( SUBSTITUTE(SUBSTITUTE(B11, "，", ","), "、", ","), ",", ), 1, 4 ), "" ) | R11: =IFERROR( INDEX( _xlfn.TEXTSPLIT( SUBSTITUTE(SUBSTITUTE(B11, "，", ","), "、", ","), ",", ), 1, 5 ), "" ) | T11: =IF(_t受注ﾌｧｲﾙ_総合計[[#This Row],[加工金額]]=_t受注ﾌｧｲﾙ_総合計[[#This Row],[受注金額(修正)]],TRUE) -> TRUE
A12: Y6-18 | B12: ｽﾗｲｽ | C12: 46198 | D12: 12000 | E12: 12000 | F12: {=_xlfn.LET( _xlpm._完了日,_加工実績DATA[加工完了日], _xlpm._調整納期列,_t受注ﾌｧｲﾙ_総合計[調整納期], _xlpm._加工完了日,_xlfn.TAKE( _xlfn._xlws.FILTER(_xlpm._完了日, (A12=_加工実績DATA[依頼NO])* (YEAR(C12) = YEAR(_xlpm._完了日)) ),1), IF(_xlpm._加工完了日 = 0,NA(),_xlpm._加工完了日) )} -> 46196 | G12: {=_xlfn.LET( _xlpm._完了日列,#REF!, _xlpm._完了日, _xlfn.TAKE( _xlfn._xlws.FILTER(_xlpm._完了日列, (A12=#REF!)* (DATEVALUE("2025/1/1") < C12) ),1 ), IFERROR(_xlpm._完了日,"") )} | H12: {=_xlfn.LET( _xlpm.f, IFERROR(F12, 0), _xlpm.g, IFERROR(G12, 0), _xlpm.c, IFERROR(C12, 0), _xlfn.IFS( ISNUMBER(_xlpm.f)*(_xlpm.f>0), _xlpm.f, ISNUMBER(_xlpm.g)*(_xlpm.g>0), _xlpm.g, ISNUMBER(_xlpm.c)*(_xlpm.c>0), _xlpm.c, TRUE, "" ) )} -> 46196 | I12: {=_xlfn.LET( _xlpm._加工金額合計列,_t月次実績表[--合計--], _xlpm._月次年月日列,_t月次実績表[年月], _xlpm._依頼NO列,_t月次実績表[依頼NO(-1除外)], IFERROR( SUM( _xlfn._xlws.FILTER(_xlpm._加工金額合計列, (A12=_xlpm._依頼NO列) * (YEAR(_xlpm._月次年月日列) = YEAR(H12)) ) ), 0) )} -> 0 | J12: =IFERROR( IF( _t受注ﾌｧｲﾙ_総合計[[#This Row],[受注金額(修正)]] > _t受注ﾌｧｲﾙ_総合計[[#This Row],[加工金額合計(月次実績)]], _t受注ﾌｧｲﾙ_総合計[[#This Row],[受注金額(修正)]], _t受注ﾌｧｲﾙ_総合計[[#This Row],[加工金額合計(月次実績)]] ), 0 ) -> 12000 | K12: =IF(ISERROR(F12),0,E12) -> 12000 | L12: =_xlfn.LET( _xlpm._依頼NO, A12, _xlpm._集計年, YEAR(H12), _xlpm._依頼列, _t受注ﾌｧｲﾙ_TPI[依頼Ｎｏ], _xlpm._集計日列, _t受注ﾌｧｲﾙ_TPI[集計日], COUNTIFS( _xlpm._依頼列, _xlpm._依頼NO, _xlpm._集計日列, ">=" & DATE(_xlpm._集計年,1,1), _xlpm._集計日列, "<" & DATE(_xlpm._集計年+1,1,1) ) ) -> 0 | M12: =_xlfn.LET( _xlpm._依頼NO, A12, _xlpm._集計年, YEAR(H12), _xlpm._依頼列,_t受注ﾌｧｲﾙ_東レ[依頼Ｎｏ], _xlpm._集計日列, _t受注ﾌｧｲﾙ_東レ[集計日], COUNTIFS( _xlpm._依頼列, _xlpm._依頼NO, _xlpm._集計日列, ">=" & DATE(_xlpm._集計年,1,1), _xlpm._集計日列, "<" & DATE(_xlpm._集計年+1,1,1) ) ) -> 1 | N12: =IFERROR( INDEX( _xlfn.TEXTSPLIT( SUBSTITUTE(SUBSTITUTE(B12, "，", ","), "、", ","), ",", ), 1, 1 ), "" ) -> ｽﾗｲｽ | O12: =IFERROR( INDEX( _xlfn.TEXTSPLIT( SUBSTITUTE(SUBSTITUTE(B12, "，", ","), "、", ","), ",", ), 1, 2 ), "" ) | P12: =IFERROR( INDEX( _xlfn.TEXTSPLIT( SUBSTITUTE(SUBSTITUTE(B12, "，", ","), "、", ","), ",", ), 1, 3 ), "" ) | Q12: =IFERROR( INDEX( _xlfn.TEXTSPLIT( SUBSTITUTE(SUBSTITUTE(B12, "，", ","), "、", ","), ",", ), 1, 4 ), "" ) | R12: =IFERROR( INDEX( _xlfn.TEXTSPLIT( SUBSTITUTE(SUBSTITUTE(B12, "，", ","), "、", ","), ",", ), 1, 5 ), "" ) | T12: =IF(_t受注ﾌｧｲﾙ_総合計[[#This Row],[加工金額]]=_t受注ﾌｧｲﾙ_総合計[[#This Row],[受注金額(修正)]],TRUE) -> TRUE
